<robot name = "robot">
    <link name="0">
        <inertial>
            <origin xyz="0 0 0.9946238298752081" rpy="0 0 0"/>
            <mass value="1" />
            <inertia ixx="100" ixy="0" ixz="0" iyy="100" iyz="0" izz="100" />
        </inertial>
        <visual>
            <origin xyz="0 0 0.9946238298752081" rpy="0 0 0"/>
            <geometry>
                <box size="1.5966197217243112 1.4954717854992718 1.7664751726092864" />
            </geometry>
            <material name="Green">
                <color rgba="0 1.0 0 1.0"/>
            </material>
        </visual>
        <collision>
            <origin xyz="0 0 0.9946238298752081" rpy="0 0 0"/>
            <geometry>
                <box size="1.5966197217243112 1.4954717854992718 1.7664751726092864" />
            </geometry>
        </collision>
    </link>
    <joint name="0_1" type="revolute">
       <parent link="0"/>
       <child  link="1"/>
       <origin rpy="0 0 0" xyz="0 0.7477358927496359 0.9946238298752081" />
       <axis xyz="1 0 0"/>
       <limit effort="0.0" lower="-3.14159" upper="3.14159" velocity="0.0"/>
    </joint>
    <link name="1">
        <inertial>
            <origin xyz="0 0.14503923988992223 0" rpy="0 0 0"/>
            <mass value="1" />
            <inertia ixx="100" ixy="0" ixz="0" iyy="100" iyz="0" izz="100" />
        </inertial>
        <visual>
            <origin xyz="0 0.14503923988992223 0" rpy="0 0 0"/>
            <geometry>
                <box size="1.9389607121123313 0.29007847977984447 0.8543018928284412" />
            </geometry>
            <material name="Green">
                <color rgba="0 1.0 0 1.0"/>
            </material>
        </visual>
        <collision>
            <origin xyz="0 0.14503923988992223 0" rpy="0 0 0"/>
            <geometry>
                <box size="1.9389607121123313 0.29007847977984447 0.8543018928284412" />
            </geometry>
        </collision>
    </link>
    <joint name="1_2" type="revolute">
       <parent link="1"/>
       <child  link="2"/>
       <origin rpy="0 0 0" xyz="0 0.29007847977984447 0" />
       <axis xyz="1 0 0"/>
       <limit effort="0.0" lower="-3.14159" upper="3.14159" velocity="0.0"/>
    </joint>
    <link name="2">
        <inertial>
            <origin xyz="0 0.26379713714119857 0" rpy="0 0 0"/>
            <mass value="1" />
            <inertia ixx="100" ixy="0" ixz="0" iyy="100" iyz="0" izz="100" />
        </inertial>
        <visual>
            <origin xyz="0 0.26379713714119857 0" rpy="0 0 0"/>
            <geometry>
                <box size="0.3638551016756389 0.5275942742823971 1.9613559854808371" />
            </geometry>
            <material name="Cyan">
                <color rgba="0 1.0 1.0 1.0"/>
            </material>
        </visual>
        <collision>
            <origin xyz="0 0.26379713714119857 0" rpy="0 0 0"/>
            <geometry>
                <box size="0.3638551016756389 0.5275942742823971 1.9613559854808371" />
            </geometry>
        </collision>
    </link>
    <joint name="2_3" type="revolute">
       <parent link="2"/>
       <child  link="3"/>
       <origin rpy="0 0 0" xyz="0 0.5275942742823971 0" />
       <axis xyz="1 0 0"/>
       <limit effort="0.0" lower="-3.14159" upper="3.14159" velocity="0.0"/>
    </joint>
    <link name="3">
        <inertial>
            <origin xyz="0 0.7012622209514404 0" rpy="0 0 0"/>
            <mass value="1" />
            <inertia ixx="100" ixy="0" ixz="0" iyy="100" iyz="0" izz="100" />
        </inertial>
        <visual>
            <origin xyz="0 0.7012622209514404 0" rpy="0 0 0"/>
            <geometry>
                <box size="0.7840490070145372 1.4025244419028808 1.7609375351888377" />
            </geometry>
            <material name="Green">
                <color rgba="0 1.0 0 1.0"/>
            </material>
        </visual>
        <collision>
            <origin xyz="0 0.7012622209514404 0" rpy="0 0 0"/>
            <geometry>
                <box size="0.7840490070145372 1.4025244419028808 1.7609375351888377" />
            </geometry>
        </collision>
    </link>
    <joint name="3_4" type="revolute">
       <parent link="3"/>
       <child  link="4"/>
       <origin rpy="0 0 0" xyz="0 1.4025244419028808 0" />
       <axis xyz="1 0 0"/>
       <limit effort="0.0" lower="-3.14159" upper="3.14159" velocity="0.0"/>
    </joint>
    <link name="4">
        <inertial>
            <origin xyz="0 0.6418085185772949 0" rpy="0 0 0"/>
            <mass value="1" />
            <inertia ixx="100" ixy="0" ixz="0" iyy="100" iyz="0" izz="100" />
        </inertial>
        <visual>
            <origin xyz="0 0.6418085185772949 0" rpy="0 0 0"/>
            <geometry>
                <box size="1.6211608049276711 1.2836170371545899 1.760509110276717" />
            </geometry>
            <material name="Cyan">
                <color rgba="0 1.0 1.0 1.0"/>
            </material>
        </visual>
        <collision>
            <origin xyz="0 0.6418085185772949 0" rpy="0 0 0"/>
            <geometry>
                <box size="1.6211608049276711 1.2836170371545899 1.760509110276717" />
            </geometry>
        </collision>
    </link>
    <joint name="4_5" type="revolute">
       <parent link="4"/>
       <child  link="5"/>
       <origin rpy="0 0 0" xyz="0 1.2836170371545899 0" />
       <axis xyz="1 0 0"/>
       <limit effort="0.0" lower="-3.14159" upper="3.14159" velocity="0.0"/>
    </joint>
    <link name="5">
        <inertial>
            <origin xyz="0 0.4236494618264459 0" rpy="0 0 0"/>
            <mass value="1" />
            <inertia ixx="100" ixy="0" ixz="0" iyy="100" iyz="0" izz="100" />
        </inertial>
        <visual>
            <origin xyz="0 0.4236494618264459 0" rpy="0 0 0"/>
            <geometry>
                <box size="1.4778864297867913 0.8472989236528918 0.7244992662047627" />
            </geometry>
            <material name="Cyan">
                <color rgba="0 1.0 1.0 1.0"/>
            </material>
        </visual>
        <collision>
            <origin xyz="0 0.4236494618264459 0" rpy="0 0 0"/>
            <geometry>
                <box size="1.4778864297867913 0.8472989236528918 0.7244992662047627" />
            </geometry>
        </collision>
    </link>
    <joint name="5_6" type="revolute">
       <parent link="5"/>
       <child  link="6"/>
       <origin rpy="0 0 0" xyz="0 0.8472989236528918 0" />
       <axis xyz="1 0 0"/>
       <limit effort="0.0" lower="-3.14159" upper="3.14159" velocity="0.0"/>
    </joint>
    <link name="6">
        <inertial>
            <origin xyz="0 0.4617866831496579 0" rpy="0 0 0"/>
            <mass value="1" />
            <inertia ixx="100" ixy="0" ixz="0" iyy="100" iyz="0" izz="100" />
        </inertial>
        <visual>
            <origin xyz="0 0.4617866831496579 0" rpy="0 0 0"/>
            <geometry>
                <box size="1.970104839197682 0.9235733662993157 1.4828660377534402" />
            </geometry>
            <material name="Cyan">
                <color rgba="0 1.0 1.0 1.0"/>
            </material>
        </visual>
        <collision>
            <origin xyz="0 0.4617866831496579 0" rpy="0 0 0"/>
            <geometry>
                <box size="1.970104839197682 0.9235733662993157 1.4828660377534402" />
            </geometry>
        </collision>
    </link>
    <joint name="6_7" type="revolute">
       <parent link="6"/>
       <child  link="7"/>
       <origin rpy="0 0 0" xyz="0 0.9235733662993157 0" />
       <axis xyz="1 0 0"/>
       <limit effort="0.0" lower="-3.14159" upper="3.14159" velocity="0.0"/>
    </joint>
    <link name="7">
        <inertial>
            <origin xyz="0 0.32614387652066273 0" rpy="0 0 0"/>
            <mass value="1" />
            <inertia ixx="100" ixy="0" ixz="0" iyy="100" iyz="0" izz="100" />
        </inertial>
        <visual>
            <origin xyz="0 0.32614387652066273 0" rpy="0 0 0"/>
            <geometry>
                <box size="1.5514988706472834 0.6522877530413255 1.9892476597504163" />
            </geometry>
            <material name="Green">
                <color rgba="0 1.0 0 1.0"/>
            </material>
        </visual>
        <collision>
            <origin xyz="0 0.32614387652066273 0" rpy="0 0 0"/>
            <geometry>
                <box size="1.5514988706472834 0.6522877530413255 1.9892476597504163" />
            </geometry>
        </collision>
    </link>
</robot>