<robot name = "robot">
    <link name="0">
        <inertial>
            <origin xyz="0 0 0.7285391336646493" rpy="0 0 0"/>
            <mass value="1" />
            <inertia ixx="100" ixy="0" ixz="0" iyy="100" iyz="0" izz="100" />
        </inertial>
        <visual>
            <origin xyz="0 0 0.7285391336646493" rpy="0 0 0"/>
            <geometry>
                <box size="1.841692697692917 1.9875277606490545 1.4550782673292986" />
            </geometry>
            <material name="Cyan">
                <color rgba="0 1.0 1.0 1.0"/>
            </material>
        </visual>
        <collision>
            <origin xyz="0 0 0.7285391336646493" rpy="0 0 0"/>
            <geometry>
                <box size="1.841692697692917 1.9875277606490545 1.4550782673292986" />
            </geometry>
        </collision>
    </link>
    <link name="1">
        <inertial>
            <origin xyz="-0.5177049091010129 0.0 0.0" rpy="0 0 0"/>
            <mass value="1" />
            <inertia ixx="100" ixy="0" ixz="0" iyy="100" iyz="0" izz="100" />
        </inertial>
        <visual>
            <origin xyz="-0.5177049091010129 0.0 0.0" rpy="0 0 0"/>
            <geometry>
                <box size="1.0354098182020257 1.7900007028946145 1.3884441019472615" />
            </geometry>
            <material name="Green">
                <color rgba="0 1.0 0 1.0"/>
            </material>
        </visual>
        <collision>
            <origin xyz="-0.5177049091010129 0.0 0.0" rpy="0 0 0"/>
            <geometry>
                <box size="1.0354098182020257 1.7900007028946145 1.3884441019472615" />
            </geometry>
        </collision>
    </link>
    <link name="2">
        <inertial>
            <origin xyz="0.0 0.7333229222190916 0.0" rpy="0 0 0"/>
            <mass value="1" />
            <inertia ixx="100" ixy="0" ixz="0" iyy="100" iyz="0" izz="100" />
        </inertial>
        <visual>
            <origin xyz="0.0 0.7333229222190916 0.0" rpy="0 0 0"/>
            <geometry>
                <box size="0.5178169274988433 1.4666458444381831 0.8034956665828464" />
            </geometry>
            <material name="Cyan">
                <color rgba="0 1.0 1.0 1.0"/>
            </material>
        </visual>
        <collision>
            <origin xyz="0.0 0.7333229222190916 0.0" rpy="0 0 0"/>
            <geometry>
                <box size="0.5178169274988433 1.4666458444381831 0.8034956665828464" />
            </geometry>
        </collision>
    </link>
    <link name="3">
        <inertial>
            <origin xyz="0.874737116488623 0.0 0.0" rpy="0 0 0"/>
            <mass value="1" />
            <inertia ixx="100" ixy="0" ixz="0" iyy="100" iyz="0" izz="100" />
        </inertial>
        <visual>
            <origin xyz="0.874737116488623 0.0 0.0" rpy="0 0 0"/>
            <geometry>
                <box size="1.749474232977246 0.3130059240006492 0.46515672129977587" />
            </geometry>
            <material name="Cyan">
                <color rgba="0 1.0 1.0 1.0"/>
            </material>
        </visual>
        <collision>
            <origin xyz="0.874737116488623 0.0 0.0" rpy="0 0 0"/>
            <geometry>
                <box size="1.749474232977246 0.3130059240006492 0.46515672129977587" />
            </geometry>
        </collision>
    </link>
    <link name="4">
        <inertial>
            <origin xyz="0.8145686986841914 0.0 0.0" rpy="0 0 0"/>
            <mass value="1" />
            <inertia ixx="100" ixy="0" ixz="0" iyy="100" iyz="0" izz="100" />
        </inertial>
        <visual>
            <origin xyz="0.8145686986841914 0.0 0.0" rpy="0 0 0"/>
            <geometry>
                <box size="1.6291373973683827 1.2147211076871844 0.47295892238487713" />
            </geometry>
            <material name="Green">
                <color rgba="0 1.0 0 1.0"/>
            </material>
        </visual>
        <collision>
            <origin xyz="0.8145686986841914 0.0 0.0" rpy="0 0 0"/>
            <geometry>
                <box size="1.6291373973683827 1.2147211076871844 0.47295892238487713" />
            </geometry>
        </collision>
    </link>
    <link name="5">
        <inertial>
            <origin xyz="-0.43372371442937435 0.0 0.0" rpy="0 0 0"/>
            <mass value="1" />
            <inertia ixx="100" ixy="0" ixz="0" iyy="100" iyz="0" izz="100" />
        </inertial>
        <visual>
            <origin xyz="-0.43372371442937435 0.0 0.0" rpy="0 0 0"/>
            <geometry>
                <box size="0.8674474288587487 0.739483897451649 1.0561707710522326" />
            </geometry>
            <material name="Green">
                <color rgba="0 1.0 0 1.0"/>
            </material>
        </visual>
        <collision>
            <origin xyz="-0.43372371442937435 0.0 0.0" rpy="0 0 0"/>
            <geometry>
                <box size="0.8674474288587487 0.739483897451649 1.0561707710522326" />
            </geometry>
        </collision>
    </link>
    <link name="6">
        <inertial>
            <origin xyz="0.0 0.2566855157285314 0.0" rpy="0 0 0"/>
            <mass value="1" />
            <inertia ixx="100" ixy="0" ixz="0" iyy="100" iyz="0" izz="100" />
        </inertial>
        <visual>
            <origin xyz="0.0 0.2566855157285314 0.0" rpy="0 0 0"/>
            <geometry>
                <box size="1.9290452547019203 0.5133710314570628 1.3510081666474059" />
            </geometry>
            <material name="Cyan">
                <color rgba="0 1.0 1.0 1.0"/>
            </material>
        </visual>
        <collision>
            <origin xyz="0.0 0.2566855157285314 0.0" rpy="0 0 0"/>
            <geometry>
                <box size="1.9290452547019203 0.5133710314570628 1.3510081666474059" />
            </geometry>
        </collision>
    </link>
    <link name="7">
        <inertial>
            <origin xyz="0.0 -0.9489201451093537 0.0" rpy="0 0 0"/>
            <mass value="1" />
            <inertia ixx="100" ixy="0" ixz="0" iyy="100" iyz="0" izz="100" />
        </inertial>
        <visual>
            <origin xyz="0.0 -0.9489201451093537 0.0" rpy="0 0 0"/>
            <geometry>
                <box size="0.506932438454133 1.8978402902187075 0.8268307722975066" />
            </geometry>
            <material name="Green">
                <color rgba="0 1.0 0 1.0"/>
            </material>
        </visual>
        <collision>
            <origin xyz="0.0 -0.9489201451093537 0.0" rpy="0 0 0"/>
            <geometry>
                <box size="0.506932438454133 1.8978402902187075 0.8268307722975066" />
            </geometry>
        </collision>
    </link>
    <joint name="0_1" type="revolute">
       <parent link="0"/>
       <child  link="1"/>
       <origin rpy="0 0 0" xyz="-0.9208463488464586 0.0 0.7285391336646493" />
       <axis xyz="0 1 0"/>
       <limit effort="0.0" lower="-3.14159" upper="3.14159" velocity="0.0"/>
    </joint>
    <joint name="1_2" type="revolute">
       <parent link="1"/>
       <child  link="2"/>
       <origin rpy="0 0 0" xyz="-0.5177049091010129 0.8950003514473073 0.0" />
       <axis xyz="0 0 1"/>
       <limit effort="0.0" lower="-3.14159" upper="3.14159" velocity="0.0"/>
    </joint>
    <joint name="0_3" type="revolute">
       <parent link="0"/>
       <child  link="3"/>
       <origin rpy="0 0 0" xyz="0.9208463488464586 0.0 0.7285391336646493" />
       <axis xyz="0 0 1"/>
       <limit effort="0.0" lower="-3.14159" upper="3.14159" velocity="0.0"/>
    </joint>
    <joint name="3_4" type="revolute">
       <parent link="3"/>
       <child  link="4"/>
       <origin rpy="0 0 0" xyz="1.749474232977246 0.0 0.0" />
       <axis xyz="0 0 1"/>
       <limit effort="0.0" lower="-3.14159" upper="3.14159" velocity="0.0"/>
    </joint>
    <joint name="1_5" type="revolute">
       <parent link="1"/>
       <child  link="5"/>
       <origin rpy="0 0 0" xyz="-1.0354098182020257 0.0 0.0" />
       <axis xyz="0 0 1"/>
       <limit effort="0.0" lower="-3.14159" upper="3.14159" velocity="0.0"/>
    </joint>
    <joint name="4_6" type="revolute">
       <parent link="4"/>
       <child  link="6"/>
       <origin rpy="0 0 0" xyz="0.8145686986841914 0.6073605538435922 0.0" />
       <axis xyz="1 0 0"/>
       <limit effort="0.0" lower="-3.14159" upper="3.14159" velocity="0.0"/>
    </joint>
    <joint name="3_7" type="revolute">
       <parent link="3"/>
       <child  link="7"/>
       <origin rpy="0 0 0" xyz="0.874737116488623 -0.1565029620003246 0.0" />
       <axis xyz="0 0 1"/>
       <limit effort="0.0" lower="-3.14159" upper="3.14159" velocity="0.0"/>
    </joint>
</robot>