<robot name = "robot">
    <link name="0">
        <inertial>
            <origin xyz="0 0 0.8646471878173513" rpy="0 0 0"/>
            <mass value="1" />
            <inertia ixx="100" ixy="0" ixz="0" iyy="100" iyz="0" izz="100" />
        </inertial>
        <visual>
            <origin xyz="0 0 0.8646471878173513" rpy="0 0 0"/>
            <geometry>
                <box size="1.634577906341245 1.187997762176286 1.7272943756347026" />
            </geometry>
            <material name="Green">
                <color rgba="0 1.0 0 1.0"/>
            </material>
        </visual>
        <collision>
            <origin xyz="0 0 0.8646471878173513" rpy="0 0 0"/>
            <geometry>
                <box size="1.634577906341245 1.187997762176286 1.7272943756347026" />
            </geometry>
        </collision>
    </link>
    <link name="1">
        <inertial>
            <origin xyz="0.3336529541337975 0.0 0.0" rpy="0 0 0"/>
            <mass value="1" />
            <inertia ixx="100" ixy="0" ixz="0" iyy="100" iyz="0" izz="100" />
        </inertial>
        <visual>
            <origin xyz="0.3336529541337975 0.0 0.0" rpy="0 0 0"/>
            <geometry>
                <box size="0.667305908267595 0.26033709629531165 1.3916679681509532" />
            </geometry>
            <material name="Cyan">
                <color rgba="0 1.0 1.0 1.0"/>
            </material>
        </visual>
        <collision>
            <origin xyz="0.3336529541337975 0.0 0.0" rpy="0 0 0"/>
            <geometry>
                <box size="0.667305908267595 0.26033709629531165 1.3916679681509532" />
            </geometry>
        </collision>
    </link>
    <link name="2">
        <inertial>
            <origin xyz="0.0 0.6343869283242145 0.0" rpy="0 0 0"/>
            <mass value="1" />
            <inertia ixx="100" ixy="0" ixz="0" iyy="100" iyz="0" izz="100" />
        </inertial>
        <visual>
            <origin xyz="0.0 0.6343869283242145 0.0" rpy="0 0 0"/>
            <geometry>
                <box size="0.6399266933326309 1.268773856648429 0.7162514704179604" />
            </geometry>
            <material name="Cyan">
                <color rgba="0 1.0 1.0 1.0"/>
            </material>
        </visual>
        <collision>
            <origin xyz="0.0 0.6343869283242145 0.0" rpy="0 0 0"/>
            <geometry>
                <box size="0.6399266933326309 1.268773856648429 0.7162514704179604" />
            </geometry>
        </collision>
    </link>
    <link name="3">
        <inertial>
            <origin xyz="0.0 0.0 0.5206987457667351" rpy="0 0 0"/>
            <mass value="1" />
            <inertia ixx="100" ixy="0" ixz="0" iyy="100" iyz="0" izz="100" />
        </inertial>
        <visual>
            <origin xyz="0.0 0.0 0.5206987457667351" rpy="0 0 0"/>
            <geometry>
                <box size="1.130127011878101 0.7136076972768861 1.0413974915334703" />
            </geometry>
            <material name="Cyan">
                <color rgba="0 1.0 1.0 1.0"/>
            </material>
        </visual>
        <collision>
            <origin xyz="0.0 0.0 0.5206987457667351" rpy="0 0 0"/>
            <geometry>
                <box size="1.130127011878101 0.7136076972768861 1.0413974915334703" />
            </geometry>
        </collision>
    </link>
    <link name="4">
        <inertial>
            <origin xyz="0.93417484587056 0.0 0.0" rpy="0 0 0"/>
            <mass value="1" />
            <inertia ixx="100" ixy="0" ixz="0" iyy="100" iyz="0" izz="100" />
        </inertial>
        <visual>
            <origin xyz="0.93417484587056 0.0 0.0" rpy="0 0 0"/>
            <geometry>
                <box size="1.86834969174112 1.5644569302668467 0.4476875034875569" />
            </geometry>
            <material name="Green">
                <color rgba="0 1.0 0 1.0"/>
            </material>
        </visual>
        <collision>
            <origin xyz="0.93417484587056 0.0 0.0" rpy="0 0 0"/>
            <geometry>
                <box size="1.86834969174112 1.5644569302668467 0.4476875034875569" />
            </geometry>
        </collision>
    </link>
    <link name="5">
        <inertial>
            <origin xyz="0.0 0.0 -0.6995070241068401" rpy="0 0 0"/>
            <mass value="1" />
            <inertia ixx="100" ixy="0" ixz="0" iyy="100" iyz="0" izz="100" />
        </inertial>
        <visual>
            <origin xyz="0.0 0.0 -0.6995070241068401" rpy="0 0 0"/>
            <geometry>
                <box size="0.3120287077529076 0.8687916074508873 1.3990140482136801" />
            </geometry>
            <material name="Cyan">
                <color rgba="0 1.0 1.0 1.0"/>
            </material>
        </visual>
        <collision>
            <origin xyz="0.0 0.0 -0.6995070241068401" rpy="0 0 0"/>
            <geometry>
                <box size="0.3120287077529076 0.8687916074508873 1.3990140482136801" />
            </geometry>
        </collision>
    </link>
    <link name="6">
        <inertial>
            <origin xyz="0.0 0.49084533951822223 0.0" rpy="0 0 0"/>
            <mass value="1" />
            <inertia ixx="100" ixy="0" ixz="0" iyy="100" iyz="0" izz="100" />
        </inertial>
        <visual>
            <origin xyz="0.0 0.49084533951822223 0.0" rpy="0 0 0"/>
            <geometry>
                <box size="1.114625591961649 0.9816906790364445 0.7039490713459498" />
            </geometry>
            <material name="Cyan">
                <color rgba="0 1.0 1.0 1.0"/>
            </material>
        </visual>
        <collision>
            <origin xyz="0.0 0.49084533951822223 0.0" rpy="0 0 0"/>
            <geometry>
                <box size="1.114625591961649 0.9816906790364445 0.7039490713459498" />
            </geometry>
        </collision>
    </link>
    <joint name="0_1" type="revolute">
       <parent link="0"/>
       <child  link="1"/>
       <origin rpy="0 0 0" xyz="0.8172889531706224 0.0 0.8646471878173513" />
       <axis xyz="0 1 0"/>
       <limit effort="0.0" lower="-3.14159" upper="3.14159" velocity="0.0"/>
    </joint>
    <joint name="0_2" type="revolute">
       <parent link="0"/>
       <child  link="2"/>
       <origin rpy="0 0 0" xyz="0.0 0.593998881088143 0.8646471878173513" />
       <axis xyz="1 0 0"/>
       <limit effort="0.0" lower="-3.14159" upper="3.14159" velocity="0.0"/>
    </joint>
    <joint name="0_3" type="revolute">
       <parent link="0"/>
       <child  link="3"/>
       <origin rpy="0 0 0" xyz="0.0 0.0 1.7282943756347025" />
       <axis xyz="0 1 0"/>
       <limit effort="0.0" lower="-3.14159" upper="3.14159" velocity="0.0"/>
    </joint>
    <joint name="3_4" type="revolute">
       <parent link="3"/>
       <child  link="4"/>
       <origin rpy="0 0 0" xyz="0.5650635059390505 0.0 0.5206987457667351" />
       <axis xyz="0 1 0"/>
       <limit effort="0.0" lower="-3.14159" upper="3.14159" velocity="0.0"/>
    </joint>
    <joint name="4_5" type="revolute">
       <parent link="4"/>
       <child  link="5"/>
       <origin rpy="0 0 0" xyz="0.93417484587056 0.0 -0.22384375174377846" />
       <axis xyz="0 1 0"/>
       <limit effort="0.0" lower="-3.14159" upper="3.14159" velocity="0.0"/>
    </joint>
    <joint name="2_6" type="revolute">
       <parent link="2"/>
       <child  link="6"/>
       <origin rpy="0 0 0" xyz="0.0 1.268773856648429 0.0" />
       <axis xyz="0 0 1"/>
       <limit effort="0.0" lower="-3.14159" upper="3.14159" velocity="0.0"/>
    </joint>
</robot>