<robot name = "robot">
    <link name="0">
        <inertial>
            <origin xyz="0 0 0.8315903082008518" rpy="0 0 0"/>
            <mass value="1" />
            <inertia ixx="100" ixy="0" ixz="0" iyy="100" iyz="0" izz="100" />
        </inertial>
        <visual>
            <origin xyz="0 0 0.8315903082008518" rpy="0 0 0"/>
            <geometry>
                <box size="1.3577060765047013 1.2538236230468152 1.6611806164017036" />
            </geometry>
            <material name="Cyan">
                <color rgba="0 1.0 1.0 1.0"/>
            </material>
        </visual>
        <collision>
            <origin xyz="0 0 0.8315903082008518" rpy="0 0 0"/>
            <geometry>
                <box size="1.3577060765047013 1.2538236230468152 1.6611806164017036" />
            </geometry>
        </collision>
    </link>
    <link name="1">
        <inertial>
            <origin xyz="0.6417667032093917 0.0 0.0" rpy="0 0 0"/>
            <mass value="1" />
            <inertia ixx="100" ixy="0" ixz="0" iyy="100" iyz="0" izz="100" />
        </inertial>
        <visual>
            <origin xyz="0.6417667032093917 0.0 0.0" rpy="0 0 0"/>
            <geometry>
                <box size="1.2835334064187833 0.6168389032470749 1.0629596027120511" />
            </geometry>
            <material name="Cyan">
                <color rgba="0 1.0 1.0 1.0"/>
            </material>
        </visual>
        <collision>
            <origin xyz="0.6417667032093917 0.0 0.0" rpy="0 0 0"/>
            <geometry>
                <box size="1.2835334064187833 0.6168389032470749 1.0629596027120511" />
            </geometry>
        </collision>
    </link>
    <link name="2">
        <inertial>
            <origin xyz="0.0 0.7998900027849488 0.0" rpy="0 0 0"/>
            <mass value="1" />
            <inertia ixx="100" ixy="0" ixz="0" iyy="100" iyz="0" izz="100" />
        </inertial>
        <visual>
            <origin xyz="0.0 0.7998900027849488 0.0" rpy="0 0 0"/>
            <geometry>
                <box size="1.6828599487655205 1.5997800055698976 1.1369229761720172" />
            </geometry>
            <material name="Green">
                <color rgba="0 1.0 0 1.0"/>
            </material>
        </visual>
        <collision>
            <origin xyz="0.0 0.7998900027849488 0.0" rpy="0 0 0"/>
            <geometry>
                <box size="1.6828599487655205 1.5997800055698976 1.1369229761720172" />
            </geometry>
        </collision>
    </link>
    <link name="3">
        <inertial>
            <origin xyz="0.0 0.6117494953782632 0.0" rpy="0 0 0"/>
            <mass value="1" />
            <inertia ixx="100" ixy="0" ixz="0" iyy="100" iyz="0" izz="100" />
        </inertial>
        <visual>
            <origin xyz="0.0 0.6117494953782632 0.0" rpy="0 0 0"/>
            <geometry>
                <box size="1.1115205327056026 1.2234989907565264 0.4640431751238982" />
            </geometry>
            <material name="Green">
                <color rgba="0 1.0 0 1.0"/>
            </material>
        </visual>
        <collision>
            <origin xyz="0.0 0.6117494953782632 0.0" rpy="0 0 0"/>
            <geometry>
                <box size="1.1115205327056026 1.2234989907565264 0.4640431751238982" />
            </geometry>
        </collision>
    </link>
    <link name="4">
        <inertial>
            <origin xyz="0.3662915089819555 0.0 0.0" rpy="0 0 0"/>
            <mass value="1" />
            <inertia ixx="100" ixy="0" ixz="0" iyy="100" iyz="0" izz="100" />
        </inertial>
        <visual>
            <origin xyz="0.3662915089819555 0.0 0.0" rpy="0 0 0"/>
            <geometry>
                <box size="0.732583017963911 0.7003691039850247 0.6783211395230619" />
            </geometry>
            <material name="Cyan">
                <color rgba="0 1.0 1.0 1.0"/>
            </material>
        </visual>
        <collision>
            <origin xyz="0.3662915089819555 0.0 0.0" rpy="0 0 0"/>
            <geometry>
                <box size="0.732583017963911 0.7003691039850247 0.6783211395230619" />
            </geometry>
        </collision>
    </link>
    <link name="5">
        <inertial>
            <origin xyz="0.0 0.0 0.9406455735706137" rpy="0 0 0"/>
            <mass value="1" />
            <inertia ixx="100" ixy="0" ixz="0" iyy="100" iyz="0" izz="100" />
        </inertial>
        <visual>
            <origin xyz="0.0 0.0 0.9406455735706137" rpy="0 0 0"/>
            <geometry>
                <box size="0.9707606577906972 1.5683967710221345 1.8812911471412275" />
            </geometry>
            <material name="Green">
                <color rgba="0 1.0 0 1.0"/>
            </material>
        </visual>
        <collision>
            <origin xyz="0.0 0.0 0.9406455735706137" rpy="0 0 0"/>
            <geometry>
                <box size="0.9707606577906972 1.5683967710221345 1.8812911471412275" />
            </geometry>
        </collision>
    </link>
    <joint name="0_1" type="revolute">
       <parent link="0"/>
       <child  link="1"/>
       <origin rpy="0 0 0" xyz="0.6788530382523507 0.0 0.8315903082008518" />
       <axis xyz="0 0 1"/>
       <limit effort="0.0" lower="-3.14159" upper="3.14159" velocity="0.0"/>
    </joint>
    <joint name="0_2" type="revolute">
       <parent link="0"/>
       <child  link="2"/>
       <origin rpy="0 0 0" xyz="0.0 0.6269118115234076 0.8315903082008518" />
       <axis xyz="1 0 0"/>
       <limit effort="0.0" lower="-3.14159" upper="3.14159" velocity="0.0"/>
    </joint>
    <joint name="1_3" type="revolute">
       <parent link="1"/>
       <child  link="3"/>
       <origin rpy="0 0 0" xyz="0.6417667032093917 0.30841945162353746 0.0" />
       <axis xyz="1 0 0"/>
       <limit effort="0.0" lower="-3.14159" upper="3.14159" velocity="0.0"/>
    </joint>
    <joint name="3_4" type="revolute">
       <parent link="3"/>
       <child  link="4"/>
       <origin rpy="0 0 0" xyz="0.5557602663528013 0.6117494953782632 0.0" />
       <axis xyz="0 1 0"/>
       <limit effort="0.0" lower="-3.14159" upper="3.14159" velocity="0.0"/>
    </joint>
    <joint name="2_5" type="revolute">
       <parent link="2"/>
       <child  link="5"/>
       <origin rpy="0 0 0" xyz="0.0 0.7998900027849488 0.5684614880860086" />
       <axis xyz="1 0 0"/>
       <limit effort="0.0" lower="-3.14159" upper="3.14159" velocity="0.0"/>
    </joint>
</robot>