<robot name = "robot">
    <link name="0">
        <inertial>
            <origin xyz="0 0 0.8569590160866272" rpy="0 0 0"/>
            <mass value="1" />
            <inertia ixx="100" ixy="0" ixz="0" iyy="100" iyz="0" izz="100" />
        </inertial>
        <visual>
            <origin xyz="0 0 0.8569590160866272" rpy="0 0 0"/>
            <geometry>
                <box size="1.136083776335023 1.838667616497441 0.5447631785858622" />
            </geometry>
            <material name="Green">
                <color rgba="0 1.0 0 1.0"/>
            </material>
        </visual>
        <collision>
            <origin xyz="0 0 0.8569590160866272" rpy="0 0 0"/>
            <geometry>
                <box size="1.136083776335023 1.838667616497441 0.5447631785858622" />
            </geometry>
        </collision>
    </link>
    <joint name="0_1" type="revolute">
       <parent link="0"/>
       <child  link="1"/>
       <origin rpy="0 0 0" xyz="0 0.9193338082487205 0.8569590160866272" />
       <axis xyz="1 0 0"/>
       <limit effort="0.0" lower="-3.14159" upper="3.14159" velocity="0.0"/>
    </joint>
    <link name="1">
        <inertial>
            <origin xyz="0 0.3251729464336015 0" rpy="0 0 0"/>
            <mass value="1" />
            <inertia ixx="100" ixy="0" ixz="0" iyy="100" iyz="0" izz="100" />
        </inertial>
        <visual>
            <origin xyz="0 0.3251729464336015 0" rpy="0 0 0"/>
            <geometry>
                <box size="1.9431805917504288 0.650345892867203 1.7139180321732543" />
            </geometry>
            <material name="Cyan">
                <color rgba="0 1.0 1.0 1.0"/>
            </material>
        </visual>
        <collision>
            <origin xyz="0 0.3251729464336015 0" rpy="0 0 0"/>
            <geometry>
                <box size="1.9431805917504288 0.650345892867203 1.7139180321732543" />
            </geometry>
        </collision>
    </link>
    <joint name="1_2" type="revolute">
       <parent link="1"/>
       <child  link="2"/>
       <origin rpy="0 0 0" xyz="0 0.650345892867203 0" />
       <axis xyz="1 0 0"/>
       <limit effort="0.0" lower="-3.14159" upper="3.14159" velocity="0.0"/>
    </joint>
    <link name="2">
        <inertial>
            <origin xyz="0 0.9332502500503896 0" rpy="0 0 0"/>
            <mass value="1" />
            <inertia ixx="100" ixy="0" ixz="0" iyy="100" iyz="0" izz="100" />
        </inertial>
        <visual>
            <origin xyz="0 0.9332502500503896 0" rpy="0 0 0"/>
            <geometry>
                <box size="1.8354382206372633 1.8665005001007793 1.313501255996813" />
            </geometry>
            <material name="Cyan">
                <color rgba="0 1.0 1.0 1.0"/>
            </material>
        </visual>
        <collision>
            <origin xyz="0 0.9332502500503896 0" rpy="0 0 0"/>
            <geometry>
                <box size="1.8354382206372633 1.8665005001007793 1.313501255996813" />
            </geometry>
        </collision>
    </link>
    <joint name="2_3" type="revolute">
       <parent link="2"/>
       <child  link="3"/>
       <origin rpy="0 0 0" xyz="0 1.8665005001007793 0" />
       <axis xyz="1 0 0"/>
       <limit effort="0.0" lower="-3.14159" upper="3.14159" velocity="0.0"/>
    </joint>
    <link name="3">
        <inertial>
            <origin xyz="0 0.7514031058867632 0" rpy="0 0 0"/>
            <mass value="1" />
            <inertia ixx="100" ixy="0" ixz="0" iyy="100" iyz="0" izz="100" />
        </inertial>
        <visual>
            <origin xyz="0 0.7514031058867632 0" rpy="0 0 0"/>
            <geometry>
                <box size="0.8651459007950117 1.5028062117735264 1.6291405393972813" />
            </geometry>
            <material name="Cyan">
                <color rgba="0 1.0 1.0 1.0"/>
            </material>
        </visual>
        <collision>
            <origin xyz="0 0.7514031058867632 0" rpy="0 0 0"/>
            <geometry>
                <box size="0.8651459007950117 1.5028062117735264 1.6291405393972813" />
            </geometry>
        </collision>
    </link>
    <joint name="3_4" type="revolute">
       <parent link="3"/>
       <child  link="4"/>
       <origin rpy="0 0 0" xyz="0 1.5028062117735264 0" />
       <axis xyz="1 0 0"/>
       <limit effort="0.0" lower="-3.14159" upper="3.14159" velocity="0.0"/>
    </joint>
    <link name="4">
        <inertial>
            <origin xyz="0 0.44045494192335344 0" rpy="0 0 0"/>
            <mass value="1" />
            <inertia ixx="100" ixy="0" ixz="0" iyy="100" iyz="0" izz="100" />
        </inertial>
        <visual>
            <origin xyz="0 0.44045494192335344 0" rpy="0 0 0"/>
            <geometry>
                <box size="0.5655639143708981 0.8809098838467069 0.3714162522125838" />
            </geometry>
            <material name="Green">
                <color rgba="0 1.0 0 1.0"/>
            </material>
        </visual>
        <collision>
            <origin xyz="0 0.44045494192335344 0" rpy="0 0 0"/>
            <geometry>
                <box size="0.5655639143708981 0.8809098838467069 0.3714162522125838" />
            </geometry>
        </collision>
    </link>
    <joint name="4_5" type="revolute">
       <parent link="4"/>
       <child  link="5"/>
       <origin rpy="0 0 0" xyz="0 0.8809098838467069 0" />
       <axis xyz="1 0 0"/>
       <limit effort="0.0" lower="-3.14159" upper="3.14159" velocity="0.0"/>
    </joint>
    <link name="5">
        <inertial>
            <origin xyz="0 0.9216010408456342 0" rpy="0 0 0"/>
            <mass value="1" />
            <inertia ixx="100" ixy="0" ixz="0" iyy="100" iyz="0" izz="100" />
        </inertial>
        <visual>
            <origin xyz="0 0.9216010408456342 0" rpy="0 0 0"/>
            <geometry>
                <box size="1.905011575842742 1.8432020816912684 1.3162480269115036" />
            </geometry>
            <material name="Green">
                <color rgba="0 1.0 0 1.0"/>
            </material>
        </visual>
        <collision>
            <origin xyz="0 0.9216010408456342 0" rpy="0 0 0"/>
            <geometry>
                <box size="1.905011575842742 1.8432020816912684 1.3162480269115036" />
            </geometry>
        </collision>
    </link>
</robot>