<robot name = "robot">
    <link name="0">
        <inertial>
            <origin xyz="0 0 0.17551514894995912" rpy="0 0 0"/>
            <mass value="1" />
            <inertia ixx="100" ixy="0" ixz="0" iyy="100" iyz="0" izz="100" />
        </inertial>
        <visual>
            <origin xyz="0 0 0.17551514894995912" rpy="0 0 0"/>
            <geometry>
                <box size="1.1016239007689568 0.2597441069556531 0.34903029789991824" />
            </geometry>
            <material name="Cyan">
                <color rgba="0 1.0 1.0 1.0"/>
            </material>
        </visual>
        <collision>
            <origin xyz="0 0 0.17551514894995912" rpy="0 0 0"/>
            <geometry>
                <box size="1.1016239007689568 0.2597441069556531 0.34903029789991824" />
            </geometry>
        </collision>
    </link>
    <link name="1">
        <inertial>
            <origin xyz="0.0 0.0 0.7980324591826365" rpy="0 0 0"/>
            <mass value="1" />
            <inertia ixx="100" ixy="0" ixz="0" iyy="100" iyz="0" izz="100" />
        </inertial>
        <visual>
            <origin xyz="0.0 0.0 0.7980324591826365" rpy="0 0 0"/>
            <geometry>
                <box size="0.5113613915329309 1.4096937197063975 1.596064918365273" />
            </geometry>
            <material name="Cyan">
                <color rgba="0 1.0 1.0 1.0"/>
            </material>
        </visual>
        <collision>
            <origin xyz="0.0 0.0 0.7980324591826365" rpy="0 0 0"/>
            <geometry>
                <box size="0.5113613915329309 1.4096937197063975 1.596064918365273" />
            </geometry>
        </collision>
    </link>
    <link name="2">
        <inertial>
            <origin xyz="0.9230790436107699 0.0 0.0" rpy="0 0 0"/>
            <mass value="1" />
            <inertia ixx="100" ixy="0" ixz="0" iyy="100" iyz="0" izz="100" />
        </inertial>
        <visual>
            <origin xyz="0.9230790436107699 0.0 0.0" rpy="0 0 0"/>
            <geometry>
                <box size="1.8461580872215397 1.174373309510283 1.3205756933514647" />
            </geometry>
            <material name="Cyan">
                <color rgba="0 1.0 1.0 1.0"/>
            </material>
        </visual>
        <collision>
            <origin xyz="0.9230790436107699 0.0 0.0" rpy="0 0 0"/>
            <geometry>
                <box size="1.8461580872215397 1.174373309510283 1.3205756933514647" />
            </geometry>
        </collision>
    </link>
    <link name="3">
        <inertial>
            <origin xyz="0.5545993088616763 0.0 0.0" rpy="0 0 0"/>
            <mass value="1" />
            <inertia ixx="100" ixy="0" ixz="0" iyy="100" iyz="0" izz="100" />
        </inertial>
        <visual>
            <origin xyz="0.5545993088616763 0.0 0.0" rpy="0 0 0"/>
            <geometry>
                <box size="1.1091986177233526 1.829358751677299 0.29156787627839964" />
            </geometry>
            <material name="Green">
                <color rgba="0 1.0 0 1.0"/>
            </material>
        </visual>
        <collision>
            <origin xyz="0.5545993088616763 0.0 0.0" rpy="0 0 0"/>
            <geometry>
                <box size="1.1091986177233526 1.829358751677299 0.29156787627839964" />
            </geometry>
        </collision>
    </link>
    <joint name="0_1" type="revolute">
       <parent link="0"/>
       <child  link="1"/>
       <origin rpy="0 0 0" xyz="0.0 0.0 0.35003029789991824" />
       <axis xyz="0 1 0"/>
       <limit effort="0.0" lower="-3.14159" upper="3.14159" velocity="0.0"/>
    </joint>
    <joint name="1_2" type="revolute">
       <parent link="1"/>
       <child  link="2"/>
       <origin rpy="0 0 0" xyz="0.25568069576646546 0.0 0.7980324591826365" />
       <axis xyz="0 1 0"/>
       <limit effort="0.0" lower="-3.14159" upper="3.14159" velocity="0.0"/>
    </joint>
    <joint name="2_3" type="revolute">
       <parent link="2"/>
       <child  link="3"/>
       <origin rpy="0 0 0" xyz="1.8461580872215397 0.0 0.0" />
       <axis xyz="0 0 1"/>
       <limit effort="0.0" lower="-3.14159" upper="3.14159" velocity="0.0"/>
    </joint>
</robot>