<robot name = "robot">
    <link name="0">
        <inertial>
            <origin xyz="0 0 0.8285414541153748" rpy="0 0 0"/>
            <mass value="1" />
            <inertia ixx="100" ixy="0" ixz="0" iyy="100" iyz="0" izz="100" />
        </inertial>
        <visual>
            <origin xyz="0 0 0.8285414541153748" rpy="0 0 0"/>
            <geometry>
                <box size="0.9930696008947832 0.9650474975059631 1.6550829082307497" />
            </geometry>
            <material name="Cyan">
                <color rgba="0 1.0 1.0 1.0"/>
            </material>
        </visual>
        <collision>
            <origin xyz="0 0 0.8285414541153748" rpy="0 0 0"/>
            <geometry>
                <box size="0.9930696008947832 0.9650474975059631 1.6550829082307497" />
            </geometry>
        </collision>
    </link>
    <link name="1">
        <inertial>
            <origin xyz="0.0 0.0 0.7690907012389347" rpy="0 0 0"/>
            <mass value="1" />
            <inertia ixx="100" ixy="0" ixz="0" iyy="100" iyz="0" izz="100" />
        </inertial>
        <visual>
            <origin xyz="0.0 0.0 0.7690907012389347" rpy="0 0 0"/>
            <geometry>
                <box size="0.5124557397297513 1.2654774094738905 1.5381814024778695" />
            </geometry>
            <material name="Green">
                <color rgba="0 1.0 0 1.0"/>
            </material>
        </visual>
        <collision>
            <origin xyz="0.0 0.0 0.7690907012389347" rpy="0 0 0"/>
            <geometry>
                <box size="0.5124557397297513 1.2654774094738905 1.5381814024778695" />
            </geometry>
        </collision>
    </link>
    <link name="2">
        <inertial>
            <origin xyz="0.558440248436609 0.0 0.0" rpy="0 0 0"/>
            <mass value="1" />
            <inertia ixx="100" ixy="0" ixz="0" iyy="100" iyz="0" izz="100" />
        </inertial>
        <visual>
            <origin xyz="0.558440248436609 0.0 0.0" rpy="0 0 0"/>
            <geometry>
                <box size="1.116880496873218 1.6656589568134668 0.6665836161569949" />
            </geometry>
            <material name="Cyan">
                <color rgba="0 1.0 1.0 1.0"/>
            </material>
        </visual>
        <collision>
            <origin xyz="0.558440248436609 0.0 0.0" rpy="0 0 0"/>
            <geometry>
                <box size="1.116880496873218 1.6656589568134668 0.6665836161569949" />
            </geometry>
        </collision>
    </link>
    <link name="3">
        <inertial>
            <origin xyz="0.0 0.0 0.9087023075447361" rpy="0 0 0"/>
            <mass value="1" />
            <inertia ixx="100" ixy="0" ixz="0" iyy="100" iyz="0" izz="100" />
        </inertial>
        <visual>
            <origin xyz="0.0 0.0 0.9087023075447361" rpy="0 0 0"/>
            <geometry>
                <box size="1.742656611958968 1.568982190495895 1.8174046150894723" />
            </geometry>
            <material name="Green">
                <color rgba="0 1.0 0 1.0"/>
            </material>
        </visual>
        <collision>
            <origin xyz="0.0 0.0 0.9087023075447361" rpy="0 0 0"/>
            <geometry>
                <box size="1.742656611958968 1.568982190495895 1.8174046150894723" />
            </geometry>
        </collision>
    </link>
    <link name="4">
        <inertial>
            <origin xyz="-0.4847019351310823 0.0 0.0" rpy="0 0 0"/>
            <mass value="1" />
            <inertia ixx="100" ixy="0" ixz="0" iyy="100" iyz="0" izz="100" />
        </inertial>
        <visual>
            <origin xyz="-0.4847019351310823 0.0 0.0" rpy="0 0 0"/>
            <geometry>
                <box size="0.9694038702621646 1.2066332274106149 0.582412117890881" />
            </geometry>
            <material name="Cyan">
                <color rgba="0 1.0 1.0 1.0"/>
            </material>
        </visual>
        <collision>
            <origin xyz="-0.4847019351310823 0.0 0.0" rpy="0 0 0"/>
            <geometry>
                <box size="0.9694038702621646 1.2066332274106149 0.582412117890881" />
            </geometry>
        </collision>
    </link>
    <link name="5">
        <inertial>
            <origin xyz="0.0 -0.2614353295345214 0.0" rpy="0 0 0"/>
            <mass value="1" />
            <inertia ixx="100" ixy="0" ixz="0" iyy="100" iyz="0" izz="100" />
        </inertial>
        <visual>
            <origin xyz="0.0 -0.2614353295345214 0.0" rpy="0 0 0"/>
            <geometry>
                <box size="0.38560783578329094 0.5228706590690428 1.2415645167248597" />
            </geometry>
            <material name="Cyan">
                <color rgba="0 1.0 1.0 1.0"/>
            </material>
        </visual>
        <collision>
            <origin xyz="0.0 -0.2614353295345214 0.0" rpy="0 0 0"/>
            <geometry>
                <box size="0.38560783578329094 0.5228706590690428 1.2415645167248597" />
            </geometry>
        </collision>
    </link>
    <link name="6">
        <inertial>
            <origin xyz="0.0 -0.8372071736726444 0.0" rpy="0 0 0"/>
            <mass value="1" />
            <inertia ixx="100" ixy="0" ixz="0" iyy="100" iyz="0" izz="100" />
        </inertial>
        <visual>
            <origin xyz="0.0 -0.8372071736726444 0.0" rpy="0 0 0"/>
            <geometry>
                <box size="1.8514220529712542 1.6744143473452888 1.9656972052981492" />
            </geometry>
            <material name="Cyan">
                <color rgba="0 1.0 1.0 1.0"/>
            </material>
        </visual>
        <collision>
            <origin xyz="0.0 -0.8372071736726444 0.0" rpy="0 0 0"/>
            <geometry>
                <box size="1.8514220529712542 1.6744143473452888 1.9656972052981492" />
            </geometry>
        </collision>
    </link>
    <joint name="0_1" type="revolute">
       <parent link="0"/>
       <child  link="1"/>
       <origin rpy="0 0 0" xyz="0.0 0.0 1.6560829082307498" />
       <axis xyz="1 0 0"/>
       <limit effort="0.0" lower="-3.14159" upper="3.14159" velocity="0.0"/>
    </joint>
    <joint name="1_2" type="revolute">
       <parent link="1"/>
       <child  link="2"/>
       <origin rpy="0 0 0" xyz="0.25622786986487567 0.0 0.7690907012389347" />
       <axis xyz="0 1 0"/>
       <limit effort="0.0" lower="-3.14159" upper="3.14159" velocity="0.0"/>
    </joint>
    <joint name="2_3" type="revolute">
       <parent link="2"/>
       <child  link="3"/>
       <origin rpy="0 0 0" xyz="0.558440248436609 0.0 0.33329180807849745" />
       <axis xyz="0 1 0"/>
       <limit effort="0.0" lower="-3.14159" upper="3.14159" velocity="0.0"/>
    </joint>
    <joint name="1_4" type="revolute">
       <parent link="1"/>
       <child  link="4"/>
       <origin rpy="0 0 0" xyz="-0.25622786986487567 0.0 0.7690907012389347" />
       <axis xyz="0 0 1"/>
       <limit effort="0.0" lower="-3.14159" upper="3.14159" velocity="0.0"/>
    </joint>
    <joint name="2_5" type="revolute">
       <parent link="2"/>
       <child  link="5"/>
       <origin rpy="0 0 0" xyz="0.558440248436609 -0.8328294784067334 0.0" />
       <axis xyz="1 0 0"/>
       <limit effort="0.0" lower="-3.14159" upper="3.14159" velocity="0.0"/>
    </joint>
    <joint name="3_6" type="revolute">
       <parent link="3"/>
       <child  link="6"/>
       <origin rpy="0 0 0" xyz="0.0 -0.7844910952479475 0.9087023075447361" />
       <axis xyz="1 0 0"/>
       <limit effort="0.0" lower="-3.14159" upper="3.14159" velocity="0.0"/>
    </joint>
</robot>