<robot name = "robot">
    <link name="0">
        <inertial>
            <origin xyz="0 0 0.7381949425157961" rpy="0 0 0"/>
            <mass value="1" />
            <inertia ixx="100" ixy="0" ixz="0" iyy="100" iyz="0" izz="100" />
        </inertial>
        <visual>
            <origin xyz="0 0 0.7381949425157961" rpy="0 0 0"/>
            <geometry>
                <box size="0.8098694297854753 1.8773080503319652 1.4743898850315922" />
            </geometry>
            <material name="Green">
                <color rgba="0 1.0 0 1.0"/>
            </material>
        </visual>
        <collision>
            <origin xyz="0 0 0.7381949425157961" rpy="0 0 0"/>
            <geometry>
                <box size="0.8098694297854753 1.8773080503319652 1.4743898850315922" />
            </geometry>
        </collision>
    </link>
    <link name="1">
        <inertial>
            <origin xyz="0.0 0.29152796080518256 0.0" rpy="0 0 0"/>
            <mass value="1" />
            <inertia ixx="100" ixy="0" ixz="0" iyy="100" iyz="0" izz="100" />
        </inertial>
        <visual>
            <origin xyz="0.0 0.29152796080518256 0.0" rpy="0 0 0"/>
            <geometry>
                <box size="1.2989096574450627 0.5830559216103651 0.727827249035645" />
            </geometry>
            <material name="Cyan">
                <color rgba="0 1.0 1.0 1.0"/>
            </material>
        </visual>
        <collision>
            <origin xyz="0.0 0.29152796080518256 0.0" rpy="0 0 0"/>
            <geometry>
                <box size="1.2989096574450627 0.5830559216103651 0.727827249035645" />
            </geometry>
        </collision>
    </link>
    <link name="2">
        <inertial>
            <origin xyz="0.0 -0.8525699549754251 0.0" rpy="0 0 0"/>
            <mass value="1" />
            <inertia ixx="100" ixy="0" ixz="0" iyy="100" iyz="0" izz="100" />
        </inertial>
        <visual>
            <origin xyz="0.0 -0.8525699549754251 0.0" rpy="0 0 0"/>
            <geometry>
                <box size="1.0164365984782782 1.7051399099508502 1.4219803443901289" />
            </geometry>
            <material name="Cyan">
                <color rgba="0 1.0 1.0 1.0"/>
            </material>
        </visual>
        <collision>
            <origin xyz="0.0 -0.8525699549754251 0.0" rpy="0 0 0"/>
            <geometry>
                <box size="1.0164365984782782 1.7051399099508502 1.4219803443901289" />
            </geometry>
        </collision>
    </link>
    <link name="3">
        <inertial>
            <origin xyz="-0.48991124188078894 0.0 0.0" rpy="0 0 0"/>
            <mass value="1" />
            <inertia ixx="100" ixy="0" ixz="0" iyy="100" iyz="0" izz="100" />
        </inertial>
        <visual>
            <origin xyz="-0.48991124188078894 0.0 0.0" rpy="0 0 0"/>
            <geometry>
                <box size="0.9798224837615779 1.69632277363709 1.0643846949748168" />
            </geometry>
            <material name="Green">
                <color rgba="0 1.0 0 1.0"/>
            </material>
        </visual>
        <collision>
            <origin xyz="-0.48991124188078894 0.0 0.0" rpy="0 0 0"/>
            <geometry>
                <box size="0.9798224837615779 1.69632277363709 1.0643846949748168" />
            </geometry>
        </collision>
    </link>
    <joint name="0_1" type="revolute">
       <parent link="0"/>
       <child  link="1"/>
       <origin rpy="0 0 0" xyz="0.0 0.9386540251659826 0.7381949425157961" />
       <axis xyz="0 0 1"/>
       <limit effort="0.0" lower="-3.14159" upper="3.14159" velocity="0.0"/>
    </joint>
    <joint name="0_2" type="revolute">
       <parent link="0"/>
       <child  link="2"/>
       <origin rpy="0 0 0" xyz="0.0 -0.9386540251659826 0.7381949425157961" />
       <axis xyz="0 0 1"/>
       <limit effort="0.0" lower="-3.14159" upper="3.14159" velocity="0.0"/>
    </joint>
    <joint name="0_3" type="revolute">
       <parent link="0"/>
       <child  link="3"/>
       <origin rpy="0 0 0" xyz="-0.40493471489273763 0.0 0.7381949425157961" />
       <axis xyz="0 1 0"/>
       <limit effort="0.0" lower="-3.14159" upper="3.14159" velocity="0.0"/>
    </joint>
</robot>