<robot name = "robot">
    <link name="0">
        <inertial>
            <origin xyz="0 0 0.20754993804382188" rpy="0 0 0"/>
            <mass value="1" />
            <inertia ixx="100" ixy="0" ixz="0" iyy="100" iyz="0" izz="100" />
        </inertial>
        <visual>
            <origin xyz="0 0 0.20754993804382188" rpy="0 0 0"/>
            <geometry>
                <box size="1.5651491240253932 1.9750811795864507 0.41309987608764376" />
            </geometry>
            <material name="Cyan">
                <color rgba="0 1.0 1.0 1.0"/>
            </material>
        </visual>
        <collision>
            <origin xyz="0 0 0.20754993804382188" rpy="0 0 0"/>
            <geometry>
                <box size="1.5651491240253932 1.9750811795864507 0.41309987608764376" />
            </geometry>
        </collision>
    </link>
    <link name="1">
        <inertial>
            <origin xyz="0.0 0.0 0.19000486433517294" rpy="0 0 0"/>
            <mass value="1" />
            <inertia ixx="100" ixy="0" ixz="0" iyy="100" iyz="0" izz="100" />
        </inertial>
        <visual>
            <origin xyz="0.0 0.0 0.19000486433517294" rpy="0 0 0"/>
            <geometry>
                <box size="1.6536904647012678 1.3436025695011755 0.3800097286703459" />
            </geometry>
            <material name="Cyan">
                <color rgba="0 1.0 1.0 1.0"/>
            </material>
        </visual>
        <collision>
            <origin xyz="0.0 0.0 0.19000486433517294" rpy="0 0 0"/>
            <geometry>
                <box size="1.6536904647012678 1.3436025695011755 0.3800097286703459" />
            </geometry>
        </collision>
    </link>
    <link name="2">
        <inertial>
            <origin xyz="0.30816545077961166 0.0 0.0" rpy="0 0 0"/>
            <mass value="1" />
            <inertia ixx="100" ixy="0" ixz="0" iyy="100" iyz="0" izz="100" />
        </inertial>
        <visual>
            <origin xyz="0.30816545077961166 0.0 0.0" rpy="0 0 0"/>
            <geometry>
                <box size="0.6163309015592233 1.3083407612390432 0.8139319805418997" />
            </geometry>
            <material name="Cyan">
                <color rgba="0 1.0 1.0 1.0"/>
            </material>
        </visual>
        <collision>
            <origin xyz="0.30816545077961166 0.0 0.0" rpy="0 0 0"/>
            <geometry>
                <box size="0.6163309015592233 1.3083407612390432 0.8139319805418997" />
            </geometry>
        </collision>
    </link>
    <link name="3">
        <inertial>
            <origin xyz="0.7677689995042204 0.0 0.0" rpy="0 0 0"/>
            <mass value="1" />
            <inertia ixx="100" ixy="0" ixz="0" iyy="100" iyz="0" izz="100" />
        </inertial>
        <visual>
            <origin xyz="0.7677689995042204 0.0 0.0" rpy="0 0 0"/>
            <geometry>
                <box size="1.5355379990084408 0.8401820603734718 0.5455840698755234" />
            </geometry>
            <material name="Green">
                <color rgba="0 1.0 0 1.0"/>
            </material>
        </visual>
        <collision>
            <origin xyz="0.7677689995042204 0.0 0.0" rpy="0 0 0"/>
            <geometry>
                <box size="1.5355379990084408 0.8401820603734718 0.5455840698755234" />
            </geometry>
        </collision>
    </link>
    <link name="4">
        <inertial>
            <origin xyz="0.476634931333802 0.0 0.0" rpy="0 0 0"/>
            <mass value="1" />
            <inertia ixx="100" ixy="0" ixz="0" iyy="100" iyz="0" izz="100" />
        </inertial>
        <visual>
            <origin xyz="0.476634931333802 0.0 0.0" rpy="0 0 0"/>
            <geometry>
                <box size="0.953269862667604 1.9420271420800024 0.9698378380001833" />
            </geometry>
            <material name="Green">
                <color rgba="0 1.0 0 1.0"/>
            </material>
        </visual>
        <collision>
            <origin xyz="0.476634931333802 0.0 0.0" rpy="0 0 0"/>
            <geometry>
                <box size="0.953269862667604 1.9420271420800024 0.9698378380001833" />
            </geometry>
        </collision>
    </link>
    <link name="5">
        <inertial>
            <origin xyz="0.0 -0.45130294486310396 0.0" rpy="0 0 0"/>
            <mass value="1" />
            <inertia ixx="100" ixy="0" ixz="0" iyy="100" iyz="0" izz="100" />
        </inertial>
        <visual>
            <origin xyz="0.0 -0.45130294486310396 0.0" rpy="0 0 0"/>
            <geometry>
                <box size="0.27506217541664646 0.9026058897262079 0.3741161346475961" />
            </geometry>
            <material name="Cyan">
                <color rgba="0 1.0 1.0 1.0"/>
            </material>
        </visual>
        <collision>
            <origin xyz="0.0 -0.45130294486310396 0.0" rpy="0 0 0"/>
            <geometry>
                <box size="0.27506217541664646 0.9026058897262079 0.3741161346475961" />
            </geometry>
        </collision>
    </link>
    <link name="6">
        <inertial>
            <origin xyz="0.0 0.25561834024721847 0.0" rpy="0 0 0"/>
            <mass value="1" />
            <inertia ixx="100" ixy="0" ixz="0" iyy="100" iyz="0" izz="100" />
        </inertial>
        <visual>
            <origin xyz="0.0 0.25561834024721847 0.0" rpy="0 0 0"/>
            <geometry>
                <box size="0.8502392462812958 0.5112366804944369 0.443040527688404" />
            </geometry>
            <material name="Cyan">
                <color rgba="0 1.0 1.0 1.0"/>
            </material>
        </visual>
        <collision>
            <origin xyz="0.0 0.25561834024721847 0.0" rpy="0 0 0"/>
            <geometry>
                <box size="0.8502392462812958 0.5112366804944369 0.443040527688404" />
            </geometry>
        </collision>
    </link>
    <joint name="0_1" type="revolute">
       <parent link="0"/>
       <child  link="1"/>
       <origin rpy="0 0 0" xyz="0.0 0.0 0.41409987608764376" />
       <axis xyz="0 1 0"/>
       <limit effort="0.0" lower="-3.14159" upper="3.14159" velocity="0.0"/>
    </joint>
    <joint name="1_2" type="revolute">
       <parent link="1"/>
       <child  link="2"/>
       <origin rpy="0 0 0" xyz="0.8268452323506339 0.0 0.19000486433517294" />
       <axis xyz="0 0 1"/>
       <limit effort="0.0" lower="-3.14159" upper="3.14159" velocity="0.0"/>
    </joint>
    <joint name="2_3" type="revolute">
       <parent link="2"/>
       <child  link="3"/>
       <origin rpy="0 0 0" xyz="0.6163309015592233 0.0 0.0" />
       <axis xyz="0 0 1"/>
       <limit effort="0.0" lower="-3.14159" upper="3.14159" velocity="0.0"/>
    </joint>
    <joint name="3_4" type="revolute">
       <parent link="3"/>
       <child  link="4"/>
       <origin rpy="0 0 0" xyz="1.5355379990084408 0.0 0.0" />
       <axis xyz="0 0 1"/>
       <limit effort="0.0" lower="-3.14159" upper="3.14159" velocity="0.0"/>
    </joint>
    <joint name="1_5" type="revolute">
       <parent link="1"/>
       <child  link="5"/>
       <origin rpy="0 0 0" xyz="0.0 -0.6718012847505878 0.19000486433517294" />
       <axis xyz="0 0 1"/>
       <limit effort="0.0" lower="-3.14159" upper="3.14159" velocity="0.0"/>
    </joint>
    <joint name="3_6" type="revolute">
       <parent link="3"/>
       <child  link="6"/>
       <origin rpy="0 0 0" xyz="0.7677689995042204 0.4200910301867359 0.0" />
       <axis xyz="1 0 0"/>
       <limit effort="0.0" lower="-3.14159" upper="3.14159" velocity="0.0"/>
    </joint>
</robot>