<robot name = "robot">
    <link name="0">
        <inertial>
            <origin xyz="0 0 0.5344766444290799" rpy="0 0 0"/>
            <mass value="1" />
            <inertia ixx="100" ixy="0" ixz="0" iyy="100" iyz="0" izz="100" />
        </inertial>
        <visual>
            <origin xyz="0 0 0.5344766444290799" rpy="0 0 0"/>
            <geometry>
                <box size="1.1011309248789953 0.5747428944463928 1.0669532888581599" />
            </geometry>
            <material name="Green">
                <color rgba="0 1.0 0 1.0"/>
            </material>
        </visual>
        <collision>
            <origin xyz="0 0 0.5344766444290799" rpy="0 0 0"/>
            <geometry>
                <box size="1.1011309248789953 0.5747428944463928 1.0669532888581599" />
            </geometry>
        </collision>
    </link>
    <link name="1">
        <inertial>
            <origin xyz="0.0 -0.6391169274502221 0.0" rpy="0 0 0"/>
            <mass value="1" />
            <inertia ixx="100" ixy="0" ixz="0" iyy="100" iyz="0" izz="100" />
        </inertial>
        <visual>
            <origin xyz="0.0 -0.6391169274502221 0.0" rpy="0 0 0"/>
            <geometry>
                <box size="0.5189410305985636 1.2782338549004442 0.35854231525168156" />
            </geometry>
            <material name="Green">
                <color rgba="0 1.0 0 1.0"/>
            </material>
        </visual>
        <collision>
            <origin xyz="0.0 -0.6391169274502221 0.0" rpy="0 0 0"/>
            <geometry>
                <box size="0.5189410305985636 1.2782338549004442 0.35854231525168156" />
            </geometry>
        </collision>
    </link>
    <link name="2">
        <inertial>
            <origin xyz="0.9882022383683026 0.0 0.0" rpy="0 0 0"/>
            <mass value="1" />
            <inertia ixx="100" ixy="0" ixz="0" iyy="100" iyz="0" izz="100" />
        </inertial>
        <visual>
            <origin xyz="0.9882022383683026 0.0 0.0" rpy="0 0 0"/>
            <geometry>
                <box size="1.9764044767366051 0.4660992229537659 0.7238249020245969" />
            </geometry>
            <material name="Cyan">
                <color rgba="0 1.0 1.0 1.0"/>
            </material>
        </visual>
        <collision>
            <origin xyz="0.9882022383683026 0.0 0.0" rpy="0 0 0"/>
            <geometry>
                <box size="1.9764044767366051 0.4660992229537659 0.7238249020245969" />
            </geometry>
        </collision>
    </link>
    <link name="3">
        <inertial>
            <origin xyz="0.0 0.0 0.3956966314700544" rpy="0 0 0"/>
            <mass value="1" />
            <inertia ixx="100" ixy="0" ixz="0" iyy="100" iyz="0" izz="100" />
        </inertial>
        <visual>
            <origin xyz="0.0 0.0 0.3956966314700544" rpy="0 0 0"/>
            <geometry>
                <box size="0.3288977343960425 1.1902639325835964 0.7913932629401088" />
            </geometry>
            <material name="Cyan">
                <color rgba="0 1.0 1.0 1.0"/>
            </material>
        </visual>
        <collision>
            <origin xyz="0.0 0.0 0.3956966314700544" rpy="0 0 0"/>
            <geometry>
                <box size="0.3288977343960425 1.1902639325835964 0.7913932629401088" />
            </geometry>
        </collision>
    </link>
    <link name="4">
        <inertial>
            <origin xyz="0.0 0.82709483447628 0.0" rpy="0 0 0"/>
            <mass value="1" />
            <inertia ixx="100" ixy="0" ixz="0" iyy="100" iyz="0" izz="100" />
        </inertial>
        <visual>
            <origin xyz="0.0 0.82709483447628 0.0" rpy="0 0 0"/>
            <geometry>
                <box size="1.5544431513671026 1.65418966895256 1.5312513968766057" />
            </geometry>
            <material name="Cyan">
                <color rgba="0 1.0 1.0 1.0"/>
            </material>
        </visual>
        <collision>
            <origin xyz="0.0 0.82709483447628 0.0" rpy="0 0 0"/>
            <geometry>
                <box size="1.5544431513671026 1.65418966895256 1.5312513968766057" />
            </geometry>
        </collision>
    </link>
    <link name="5">
        <inertial>
            <origin xyz="0.19729452752022503 0.0 0.0" rpy="0 0 0"/>
            <mass value="1" />
            <inertia ixx="100" ixy="0" ixz="0" iyy="100" iyz="0" izz="100" />
        </inertial>
        <visual>
            <origin xyz="0.19729452752022503 0.0 0.0" rpy="0 0 0"/>
            <geometry>
                <box size="0.39458905504045005 0.35876883671972915 1.013421141237564" />
            </geometry>
            <material name="Green">
                <color rgba="0 1.0 0 1.0"/>
            </material>
        </visual>
        <collision>
            <origin xyz="0.19729452752022503 0.0 0.0" rpy="0 0 0"/>
            <geometry>
                <box size="0.39458905504045005 0.35876883671972915 1.013421141237564" />
            </geometry>
        </collision>
    </link>
    <link name="6">
        <inertial>
            <origin xyz="0.0 0.9532101260450939 0.0" rpy="0 0 0"/>
            <mass value="1" />
            <inertia ixx="100" ixy="0" ixz="0" iyy="100" iyz="0" izz="100" />
        </inertial>
        <visual>
            <origin xyz="0.0 0.9532101260450939 0.0" rpy="0 0 0"/>
            <geometry>
                <box size="1.4581501676060247 1.9064202520901878 0.7649920980922096" />
            </geometry>
            <material name="Cyan">
                <color rgba="0 1.0 1.0 1.0"/>
            </material>
        </visual>
        <collision>
            <origin xyz="0.0 0.9532101260450939 0.0" rpy="0 0 0"/>
            <geometry>
                <box size="1.4581501676060247 1.9064202520901878 0.7649920980922096" />
            </geometry>
        </collision>
    </link>
    <joint name="0_1" type="revolute">
       <parent link="0"/>
       <child  link="1"/>
       <origin rpy="0 0 0" xyz="0.0 -0.2873714472231964 0.5344766444290799" />
       <axis xyz="0 0 1"/>
       <limit effort="0.0" lower="-3.14159" upper="3.14159" velocity="0.0"/>
    </joint>
    <joint name="0_2" type="revolute">
       <parent link="0"/>
       <child  link="2"/>
       <origin rpy="0 0 0" xyz="0.5505654624394977 0.0 0.5344766444290799" />
       <axis xyz="0 0 1"/>
       <limit effort="0.0" lower="-3.14159" upper="3.14159" velocity="0.0"/>
    </joint>
    <joint name="0_3" type="revolute">
       <parent link="0"/>
       <child  link="3"/>
       <origin rpy="0 0 0" xyz="0.0 0.0 1.0679532888581598" />
       <axis xyz="1 0 0"/>
       <limit effort="0.0" lower="-3.14159" upper="3.14159" velocity="0.0"/>
    </joint>
    <joint name="3_4" type="revolute">
       <parent link="3"/>
       <child  link="4"/>
       <origin rpy="0 0 0" xyz="0.0 0.5951319662917982 0.3956966314700544" />
       <axis xyz="1 0 0"/>
       <limit effort="0.0" lower="-3.14159" upper="3.14159" velocity="0.0"/>
    </joint>
    <joint name="3_5" type="revolute">
       <parent link="3"/>
       <child  link="5"/>
       <origin rpy="0 0 0" xyz="0.16444886719802124 0.0 0.3956966314700544" />
       <axis xyz="0 1 0"/>
       <limit effort="0.0" lower="-3.14159" upper="3.14159" velocity="0.0"/>
    </joint>
    <joint name="4_6" type="revolute">
       <parent link="4"/>
       <child  link="6"/>
       <origin rpy="0 0 0" xyz="0.0 1.65418966895256 0.0" />
       <axis xyz="1 0 0"/>
       <limit effort="0.0" lower="-3.14159" upper="3.14159" velocity="0.0"/>
    </joint>
</robot>