<robot name = "robot">
    <link name="0">
        <inertial>
            <origin xyz="0 0 0.5373119534222773" rpy="0 0 0"/>
            <mass value="1" />
            <inertia ixx="100" ixy="0" ixz="0" iyy="100" iyz="0" izz="100" />
        </inertial>
        <visual>
            <origin xyz="0 0 0.5373119534222773" rpy="0 0 0"/>
            <geometry>
                <box size="1.9633976184344986 0.9273202143355472 1.0726239068445547" />
            </geometry>
            <material name="Green">
                <color rgba="0 1.0 0 1.0"/>
            </material>
        </visual>
        <collision>
            <origin xyz="0 0 0.5373119534222773" rpy="0 0 0"/>
            <geometry>
                <box size="1.9633976184344986 0.9273202143355472 1.0726239068445547" />
            </geometry>
        </collision>
    </link>
    <link name="1">
        <inertial>
            <origin xyz="0.0 0.0 0.5835412324941744" rpy="0 0 0"/>
            <mass value="1" />
            <inertia ixx="100" ixy="0" ixz="0" iyy="100" iyz="0" izz="100" />
        </inertial>
        <visual>
            <origin xyz="0.0 0.0 0.5835412324941744" rpy="0 0 0"/>
            <geometry>
                <box size="0.38613819985925035 1.424850800018467 1.1670824649883489" />
            </geometry>
            <material name="Green">
                <color rgba="0 1.0 0 1.0"/>
            </material>
        </visual>
        <collision>
            <origin xyz="0.0 0.0 0.5835412324941744" rpy="0 0 0"/>
            <geometry>
                <box size="0.38613819985925035 1.424850800018467 1.1670824649883489" />
            </geometry>
        </collision>
    </link>
    <link name="2">
        <inertial>
            <origin xyz="0.0 0.0 0.960494524087467" rpy="0 0 0"/>
            <mass value="1" />
            <inertia ixx="100" ixy="0" ixz="0" iyy="100" iyz="0" izz="100" />
        </inertial>
        <visual>
            <origin xyz="0.0 0.0 0.960494524087467" rpy="0 0 0"/>
            <geometry>
                <box size="1.0560265873322678 0.8009986117266679 1.920989048174934" />
            </geometry>
            <material name="Cyan">
                <color rgba="0 1.0 1.0 1.0"/>
            </material>
        </visual>
        <collision>
            <origin xyz="0.0 0.0 0.960494524087467" rpy="0 0 0"/>
            <geometry>
                <box size="1.0560265873322678 0.8009986117266679 1.920989048174934" />
            </geometry>
        </collision>
    </link>
    <link name="3">
        <inertial>
            <origin xyz="0.0 0.9644817917669228 0.0" rpy="0 0 0"/>
            <mass value="1" />
            <inertia ixx="100" ixy="0" ixz="0" iyy="100" iyz="0" izz="100" />
        </inertial>
        <visual>
            <origin xyz="0.0 0.9644817917669228 0.0" rpy="0 0 0"/>
            <geometry>
                <box size="0.624455122694424 1.9289635835338457 0.43816355211222946" />
            </geometry>
            <material name="Cyan">
                <color rgba="0 1.0 1.0 1.0"/>
            </material>
        </visual>
        <collision>
            <origin xyz="0.0 0.9644817917669228 0.0" rpy="0 0 0"/>
            <geometry>
                <box size="0.624455122694424 1.9289635835338457 0.43816355211222946" />
            </geometry>
        </collision>
    </link>
    <link name="4">
        <inertial>
            <origin xyz="-0.49401142840985135 0.0 0.0" rpy="0 0 0"/>
            <mass value="1" />
            <inertia ixx="100" ixy="0" ixz="0" iyy="100" iyz="0" izz="100" />
        </inertial>
        <visual>
            <origin xyz="-0.49401142840985135 0.0 0.0" rpy="0 0 0"/>
            <geometry>
                <box size="0.9880228568197027 1.8367782532430823 1.8074888169044834" />
            </geometry>
            <material name="Green">
                <color rgba="0 1.0 0 1.0"/>
            </material>
        </visual>
        <collision>
            <origin xyz="-0.49401142840985135 0.0 0.0" rpy="0 0 0"/>
            <geometry>
                <box size="0.9880228568197027 1.8367782532430823 1.8074888169044834" />
            </geometry>
        </collision>
    </link>
    <link name="5">
        <inertial>
            <origin xyz="0.0 0.13732608040453967 0.0" rpy="0 0 0"/>
            <mass value="1" />
            <inertia ixx="100" ixy="0" ixz="0" iyy="100" iyz="0" izz="100" />
        </inertial>
        <visual>
            <origin xyz="0.0 0.13732608040453967 0.0" rpy="0 0 0"/>
            <geometry>
                <box size="1.2823879789897503 0.27465216080907934 0.9209397248377716" />
            </geometry>
            <material name="Green">
                <color rgba="0 1.0 0 1.0"/>
            </material>
        </visual>
        <collision>
            <origin xyz="0.0 0.13732608040453967 0.0" rpy="0 0 0"/>
            <geometry>
                <box size="1.2823879789897503 0.27465216080907934 0.9209397248377716" />
            </geometry>
        </collision>
    </link>
    <link name="6">
        <inertial>
            <origin xyz="-0.14251937148160473 0.0 0.0" rpy="0 0 0"/>
            <mass value="1" />
            <inertia ixx="100" ixy="0" ixz="0" iyy="100" iyz="0" izz="100" />
        </inertial>
        <visual>
            <origin xyz="-0.14251937148160473 0.0 0.0" rpy="0 0 0"/>
            <geometry>
                <box size="0.28503874296320947 1.0742776884724323 0.7826454314034831" />
            </geometry>
            <material name="Cyan">
                <color rgba="0 1.0 1.0 1.0"/>
            </material>
        </visual>
        <collision>
            <origin xyz="-0.14251937148160473 0.0 0.0" rpy="0 0 0"/>
            <geometry>
                <box size="0.28503874296320947 1.0742776884724323 0.7826454314034831" />
            </geometry>
        </collision>
    </link>
    <joint name="0_1" type="revolute">
       <parent link="0"/>
       <child  link="1"/>
       <origin rpy="0 0 0" xyz="0.0 0.0 1.0736239068445546" />
       <axis xyz="0 1 0"/>
       <limit effort="0.0" lower="-3.14159" upper="3.14159" velocity="0.0"/>
    </joint>
    <joint name="1_2" type="revolute">
       <parent link="1"/>
       <child  link="2"/>
       <origin rpy="0 0 0" xyz="0.0 0.0 1.1670824649883489" />
       <axis xyz="1 0 0"/>
       <limit effort="0.0" lower="-3.14159" upper="3.14159" velocity="0.0"/>
    </joint>
    <joint name="0_3" type="revolute">
       <parent link="0"/>
       <child  link="3"/>
       <origin rpy="0 0 0" xyz="0.0 0.4636601071677736 0.5373119534222773" />
       <axis xyz="1 0 0"/>
       <limit effort="0.0" lower="-3.14159" upper="3.14159" velocity="0.0"/>
    </joint>
    <joint name="2_4" type="revolute">
       <parent link="2"/>
       <child  link="4"/>
       <origin rpy="0 0 0" xyz="-0.5280132936661339 0.0 0.960494524087467" />
       <axis xyz="0 1 0"/>
       <limit effort="0.0" lower="-3.14159" upper="3.14159" velocity="0.0"/>
    </joint>
    <joint name="3_5" type="revolute">
       <parent link="3"/>
       <child  link="5"/>
       <origin rpy="0 0 0" xyz="0.0 1.9289635835338457 0.0" />
       <axis xyz="1 0 0"/>
       <limit effort="0.0" lower="-3.14159" upper="3.14159" velocity="0.0"/>
    </joint>
    <joint name="4_6" type="revolute">
       <parent link="4"/>
       <child  link="6"/>
       <origin rpy="0 0 0" xyz="-0.9880228568197027 0.0 0.0" />
       <axis xyz="0 1 0"/>
       <limit effort="0.0" lower="-3.14159" upper="3.14159" velocity="0.0"/>
    </joint>
</robot>