<robot name = "robot">
    <link name="0">
        <inertial>
            <origin xyz="0 0 0.5810770726974925" rpy="0 0 0"/>
            <mass value="1" />
            <inertia ixx="100" ixy="0" ixz="0" iyy="100" iyz="0" izz="100" />
        </inertial>
        <visual>
            <origin xyz="0 0 0.5810770726974925" rpy="0 0 0"/>
            <geometry>
                <box size="1.5665007892962808 1.3230232467133602 1.160154145394985" />
            </geometry>
            <material name="Cyan">
                <color rgba="0 1.0 1.0 1.0"/>
            </material>
        </visual>
        <collision>
            <origin xyz="0 0 0.5810770726974925" rpy="0 0 0"/>
            <geometry>
                <box size="1.5665007892962808 1.3230232467133602 1.160154145394985" />
            </geometry>
        </collision>
    </link>
    <link name="1">
        <inertial>
            <origin xyz="0.0 0.0 0.7499603398502807" rpy="0 0 0"/>
            <mass value="1" />
            <inertia ixx="100" ixy="0" ixz="0" iyy="100" iyz="0" izz="100" />
        </inertial>
        <visual>
            <origin xyz="0.0 0.0 0.7499603398502807" rpy="0 0 0"/>
            <geometry>
                <box size="0.5161871700044827 0.6175652485835595 1.4999206797005613" />
            </geometry>
            <material name="Green">
                <color rgba="0 1.0 0 1.0"/>
            </material>
        </visual>
        <collision>
            <origin xyz="0.0 0.0 0.7499603398502807" rpy="0 0 0"/>
            <geometry>
                <box size="0.5161871700044827 0.6175652485835595 1.4999206797005613" />
            </geometry>
        </collision>
    </link>
    <link name="2">
        <inertial>
            <origin xyz="0.0 0.922391737331393 0.0" rpy="0 0 0"/>
            <mass value="1" />
            <inertia ixx="100" ixy="0" ixz="0" iyy="100" iyz="0" izz="100" />
        </inertial>
        <visual>
            <origin xyz="0.0 0.922391737331393 0.0" rpy="0 0 0"/>
            <geometry>
                <box size="0.6953979998989138 1.844783474662786 0.3884149043002515" />
            </geometry>
            <material name="Cyan">
                <color rgba="0 1.0 1.0 1.0"/>
            </material>
        </visual>
        <collision>
            <origin xyz="0.0 0.922391737331393 0.0" rpy="0 0 0"/>
            <geometry>
                <box size="0.6953979998989138 1.844783474662786 0.3884149043002515" />
            </geometry>
        </collision>
    </link>
    <joint name="0_1" type="revolute">
       <parent link="0"/>
       <child  link="1"/>
       <origin rpy="0 0 0" xyz="0.0 0.0 1.1611541453949852" />
       <axis xyz="1 0 0"/>
       <limit effort="0.0" lower="-3.14159" upper="3.14159" velocity="0.0"/>
    </joint>
    <joint name="1_2" type="revolute">
       <parent link="1"/>
       <child  link="2"/>
       <origin rpy="0 0 0" xyz="0.0 0.3087826242917798 0.7499603398502807" />
       <axis xyz="1 0 0"/>
       <limit effort="0.0" lower="-3.14159" upper="3.14159" velocity="0.0"/>
    </joint>
</robot>