<robot name = "robot">
    <link name="0">
        <inertial>
            <origin xyz="0 0 0.5732304598144392" rpy="0 0 0"/>
            <mass value="1" />
            <inertia ixx="100" ixy="0" ixz="0" iyy="100" iyz="0" izz="100" />
        </inertial>
        <visual>
            <origin xyz="0 0 0.5732304598144392" rpy="0 0 0"/>
            <geometry>
                <box size="0.9729912655393773 1.5518810336375812 1.1444609196288784" />
            </geometry>
            <material name="Green">
                <color rgba="0 1.0 0 1.0"/>
            </material>
        </visual>
        <collision>
            <origin xyz="0 0 0.5732304598144392" rpy="0 0 0"/>
            <geometry>
                <box size="0.9729912655393773 1.5518810336375812 1.1444609196288784" />
            </geometry>
        </collision>
    </link>
    <link name="1">
        <inertial>
            <origin xyz="0.5866466384470461 0.0 0.0" rpy="0 0 0"/>
            <mass value="1" />
            <inertia ixx="100" ixy="0" ixz="0" iyy="100" iyz="0" izz="100" />
        </inertial>
        <visual>
            <origin xyz="0.5866466384470461 0.0 0.0" rpy="0 0 0"/>
            <geometry>
                <box size="1.1732932768940922 0.6225779719072024 0.8431109218831216" />
            </geometry>
            <material name="Cyan">
                <color rgba="0 1.0 1.0 1.0"/>
            </material>
        </visual>
        <collision>
            <origin xyz="0.5866466384470461 0.0 0.0" rpy="0 0 0"/>
            <geometry>
                <box size="1.1732932768940922 0.6225779719072024 0.8431109218831216" />
            </geometry>
        </collision>
    </link>
    <link name="2">
        <inertial>
            <origin xyz="0.0 0.0 0.7862169383105626" rpy="0 0 0"/>
            <mass value="1" />
            <inertia ixx="100" ixy="0" ixz="0" iyy="100" iyz="0" izz="100" />
        </inertial>
        <visual>
            <origin xyz="0.0 0.0 0.7862169383105626" rpy="0 0 0"/>
            <geometry>
                <box size="1.8205432337644416 1.5572270382202436 1.5724338766211252" />
            </geometry>
            <material name="Cyan">
                <color rgba="0 1.0 1.0 1.0"/>
            </material>
        </visual>
        <collision>
            <origin xyz="0.0 0.0 0.7862169383105626" rpy="0 0 0"/>
            <geometry>
                <box size="1.8205432337644416 1.5572270382202436 1.5724338766211252" />
            </geometry>
        </collision>
    </link>
    <link name="3">
        <inertial>
            <origin xyz="0.0 0.1755043158643121 0.0" rpy="0 0 0"/>
            <mass value="1" />
            <inertia ixx="100" ixy="0" ixz="0" iyy="100" iyz="0" izz="100" />
        </inertial>
        <visual>
            <origin xyz="0.0 0.1755043158643121 0.0" rpy="0 0 0"/>
            <geometry>
                <box size="1.4364483094943834 0.3510086317286242 1.104201695469817" />
            </geometry>
            <material name="Cyan">
                <color rgba="0 1.0 1.0 1.0"/>
            </material>
        </visual>
        <collision>
            <origin xyz="0.0 0.1755043158643121 0.0" rpy="0 0 0"/>
            <geometry>
                <box size="1.4364483094943834 0.3510086317286242 1.104201695469817" />
            </geometry>
        </collision>
    </link>
    <link name="4">
        <inertial>
            <origin xyz="0.5972892827411073 0.0 0.0" rpy="0 0 0"/>
            <mass value="1" />
            <inertia ixx="100" ixy="0" ixz="0" iyy="100" iyz="0" izz="100" />
        </inertial>
        <visual>
            <origin xyz="0.5972892827411073 0.0 0.0" rpy="0 0 0"/>
            <geometry>
                <box size="1.1945785654822145 0.6102589178308527 0.8880139499628614" />
            </geometry>
            <material name="Cyan">
                <color rgba="0 1.0 1.0 1.0"/>
            </material>
        </visual>
        <collision>
            <origin xyz="0.5972892827411073 0.0 0.0" rpy="0 0 0"/>
            <geometry>
                <box size="1.1945785654822145 0.6102589178308527 0.8880139499628614" />
            </geometry>
        </collision>
    </link>
    <joint name="0_1" type="revolute">
       <parent link="0"/>
       <child  link="1"/>
       <origin rpy="0 0 0" xyz="0.48649563276968866 0.0 0.5732304598144392" />
       <axis xyz="0 0 1"/>
       <limit effort="0.0" lower="-3.14159" upper="3.14159" velocity="0.0"/>
    </joint>
    <joint name="0_2" type="revolute">
       <parent link="0"/>
       <child  link="2"/>
       <origin rpy="0 0 0" xyz="0.0 0.0 1.1454609196288783" />
       <axis xyz="1 0 0"/>
       <limit effort="0.0" lower="-3.14159" upper="3.14159" velocity="0.0"/>
    </joint>
    <joint name="2_3" type="revolute">
       <parent link="2"/>
       <child  link="3"/>
       <origin rpy="0 0 0" xyz="0.0 0.7786135191101218 0.7862169383105626" />
       <axis xyz="1 0 0"/>
       <limit effort="0.0" lower="-3.14159" upper="3.14159" velocity="0.0"/>
    </joint>
    <joint name="1_4" type="revolute">
       <parent link="1"/>
       <child  link="4"/>
       <origin rpy="0 0 0" xyz="1.1732932768940922 0.0 0.0" />
       <axis xyz="0 1 0"/>
       <limit effort="0.0" lower="-3.14159" upper="3.14159" velocity="0.0"/>
    </joint>
</robot>