<robot name = "robot">
    <link name="0">
        <inertial>
            <origin xyz="0 0 0.6707856455380363" rpy="0 0 0"/>
            <mass value="1" />
            <inertia ixx="100" ixy="0" ixz="0" iyy="100" iyz="0" izz="100" />
        </inertial>
        <visual>
            <origin xyz="0 0 0.6707856455380363" rpy="0 0 0"/>
            <geometry>
                <box size="1.0718051094001555 1.4340504741577482 1.3395712910760726" />
            </geometry>
            <material name="Green">
                <color rgba="0 1.0 0 1.0"/>
            </material>
        </visual>
        <collision>
            <origin xyz="0 0 0.6707856455380363" rpy="0 0 0"/>
            <geometry>
                <box size="1.0718051094001555 1.4340504741577482 1.3395712910760726" />
            </geometry>
        </collision>
    </link>
    <link name="1">
        <inertial>
            <origin xyz="0.0 0.0 0.2818549554787332" rpy="0 0 0"/>
            <mass value="1" />
            <inertia ixx="100" ixy="0" ixz="0" iyy="100" iyz="0" izz="100" />
        </inertial>
        <visual>
            <origin xyz="0.0 0.0 0.2818549554787332" rpy="0 0 0"/>
            <geometry>
                <box size="0.9008188404715624 0.9737082946713811 0.5637099109574664" />
            </geometry>
            <material name="Green">
                <color rgba="0 1.0 0 1.0"/>
            </material>
        </visual>
        <collision>
            <origin xyz="0.0 0.0 0.2818549554787332" rpy="0 0 0"/>
            <geometry>
                <box size="0.9008188404715624 0.9737082946713811 0.5637099109574664" />
            </geometry>
        </collision>
    </link>
    <link name="2">
        <inertial>
            <origin xyz="0.8032481601268036 0.0 0.0" rpy="0 0 0"/>
            <mass value="1" />
            <inertia ixx="100" ixy="0" ixz="0" iyy="100" iyz="0" izz="100" />
        </inertial>
        <visual>
            <origin xyz="0.8032481601268036 0.0 0.0" rpy="0 0 0"/>
            <geometry>
                <box size="1.6064963202536071 1.6948481248561968 0.686116396308788" />
            </geometry>
            <material name="Cyan">
                <color rgba="0 1.0 1.0 1.0"/>
            </material>
        </visual>
        <collision>
            <origin xyz="0.8032481601268036 0.0 0.0" rpy="0 0 0"/>
            <geometry>
                <box size="1.6064963202536071 1.6948481248561968 0.686116396308788" />
            </geometry>
        </collision>
    </link>
    <link name="3">
        <inertial>
            <origin xyz="0.0 0.6047452965623092 0.0" rpy="0 0 0"/>
            <mass value="1" />
            <inertia ixx="100" ixy="0" ixz="0" iyy="100" iyz="0" izz="100" />
        </inertial>
        <visual>
            <origin xyz="0.0 0.6047452965623092 0.0" rpy="0 0 0"/>
            <geometry>
                <box size="1.8095881243945806 1.2094905931246185 0.2870001514570233" />
            </geometry>
            <material name="Cyan">
                <color rgba="0 1.0 1.0 1.0"/>
            </material>
        </visual>
        <collision>
            <origin xyz="0.0 0.6047452965623092 0.0" rpy="0 0 0"/>
            <geometry>
                <box size="1.8095881243945806 1.2094905931246185 0.2870001514570233" />
            </geometry>
        </collision>
    </link>
    <joint name="0_1" type="revolute">
       <parent link="0"/>
       <child  link="1"/>
       <origin rpy="0 0 0" xyz="0.0 0.0 1.3405712910760728" />
       <axis xyz="0 1 0"/>
       <limit effort="0.0" lower="-3.14159" upper="3.14159" velocity="0.0"/>
    </joint>
    <joint name="0_2" type="revolute">
       <parent link="0"/>
       <child  link="2"/>
       <origin rpy="0 0 0" xyz="0.5359025547000777 0.0 0.6707856455380363" />
       <axis xyz="0 1 0"/>
       <limit effort="0.0" lower="-3.14159" upper="3.14159" velocity="0.0"/>
    </joint>
    <joint name="1_3" type="revolute">
       <parent link="1"/>
       <child  link="3"/>
       <origin rpy="0 0 0" xyz="0.0 0.48685414733569055 0.2818549554787332" />
       <axis xyz="1 0 0"/>
       <limit effort="0.0" lower="-3.14159" upper="3.14159" velocity="0.0"/>
    </joint>
</robot>