<robot name = "robot">
    <link name="0">
        <inertial>
            <origin xyz="0 0 0.22027856604209994" rpy="0 0 0"/>
            <mass value="1" />
            <inertia ixx="100" ixy="0" ixz="0" iyy="100" iyz="0" izz="100" />
        </inertial>
        <visual>
            <origin xyz="0 0 0.22027856604209994" rpy="0 0 0"/>
            <geometry>
                <box size="0.6973329699347793 1.2554654729408015 0.4405571320841999" />
            </geometry>
            <material name="Cyan">
                <color rgba="0 1.0 1.0 1.0"/>
            </material>
        </visual>
        <collision>
            <origin xyz="0 0 0.22027856604209994" rpy="0 0 0"/>
            <geometry>
                <box size="0.6973329699347793 1.2554654729408015 0.4405571320841999" />
            </geometry>
        </collision>
    </link>
    <link name="1">
        <inertial>
            <origin xyz="0.0 0.0 -0.7146175119394004" rpy="0 0 0"/>
            <mass value="1" />
            <inertia ixx="100" ixy="0" ixz="0" iyy="100" iyz="0" izz="100" />
        </inertial>
        <visual>
            <origin xyz="0.0 0.0 -0.7146175119394004" rpy="0 0 0"/>
            <geometry>
                <box size="0.5470425062953599 1.0967047031237709 0.9886778917946009" />
            </geometry>
            <material name="Cyan">
                <color rgba="0 1.0 1.0 1.0"/>
            </material>
        </visual>
        <collision>
            <origin xyz="0.0 0.0 -0.7146175119394004" rpy="0 0 0"/>
            <geometry>
                <box size="0.5470425062953599 1.0967047031237709 0.9886778917946009" />
            </geometry>
        </collision>
    </link>
    <link name="2">
        <inertial>
            <origin xyz="0.0 0.8476365246715227 0.2740603798552005" rpy="0 0 0"/>
            <mass value="1" />
            <inertia ixx="100" ixy="0" ixz="0" iyy="100" iyz="0" izz="100" />
        </inertial>
        <visual>
            <origin xyz="0.0 0.8476365246715227 0.2740603798552005" rpy="0 0 0"/>
            <geometry>
                <box size="0.43179059778958406 0.5985683462192746 1.6576243035135132" />
            </geometry>
            <material name="Green">
                <color rgba="0 1.0 0 1.0"/>
            </material>
        </visual>
        <collision>
            <origin xyz="0.0 0.8476365246715227 0.2740603798552005" rpy="0 0 0"/>
            <geometry>
                <box size="0.43179059778958406 0.5985683462192746 1.6576243035135132" />
            </geometry>
        </collision>
    </link>
    <link name="3">
        <inertial>
            <origin xyz="0.0 -0.6936861196660091 0.2740603798552005" rpy="0 0 0"/>
            <mass value="1" />
            <inertia ixx="100" ixy="0" ixz="0" iyy="100" iyz="0" izz="100" />
        </inertial>
        <visual>
            <origin xyz="0.0 -0.6936861196660091 0.2740603798552005" rpy="0 0 0"/>
            <geometry>
                <box size="1.6409077190649333 0.29066753620824737 1.664747003349373" />
            </geometry>
            <material name="Cyan">
                <color rgba="0 1.0 1.0 1.0"/>
            </material>
        </visual>
        <collision>
            <origin xyz="0.0 -0.6936861196660091 0.2740603798552005" rpy="0 0 0"/>
            <geometry>
                <box size="1.6409077190649333 0.29066753620824737 1.664747003349373" />
            </geometry>
        </collision>
    </link>
    <joint name="0_1" type="revolute">
       <parent link="0"/>
       <child  link="1"/>
       <origin rpy="0 0 0" xyz="0.0 0.0 -0.22027856604209994" />
       <axis xyz="0 1 0"/>
       <limit effort="0.0" lower="-3.14159" upper="3.14159" velocity="0.0"/>
    </joint>
    <joint name="1_2" type="revolute">
       <parent link="1"/>
       <child  link="2"/>
       <origin rpy="0 0 0" xyz="0.0 0.5483523515618854 0.2740603798552005" />
       <axis xyz="1 0 0"/>
       <limit effort="0.0" lower="-3.14159" upper="3.14159" velocity="0.0"/>
    </joint>
    <joint name="1_3" type="revolute">
       <parent link="1"/>
       <child  link="3"/>
       <origin rpy="0 0 0" xyz="0.0 -0.5483523515618854 0.2740603798552005" />
       <axis xyz="1 0 0"/>
       <limit effort="0.0" lower="-3.14159" upper="3.14159" velocity="0.0"/>
    </joint>
</robot>