<robot name = "robot">
    <link name="0">
        <inertial>
            <origin xyz="0 0 0.9008601726714839" rpy="0 0 0"/>
            <mass value="1" />
            <inertia ixx="100" ixy="0" ixz="0" iyy="100" iyz="0" izz="100" />
        </inertial>
        <visual>
            <origin xyz="0 0 0.9008601726714839" rpy="0 0 0"/>
            <geometry>
                <box size="1.414076011075207 1.1217983775436045 1.7997203453429678" />
            </geometry>
            <material name="Cyan">
                <color rgba="0 1.0 1.0 1.0"/>
            </material>
        </visual>
        <collision>
            <origin xyz="0 0 0.9008601726714839" rpy="0 0 0"/>
            <geometry>
                <box size="1.414076011075207 1.1217983775436045 1.7997203453429678" />
            </geometry>
        </collision>
    </link>
    <link name="1">
        <inertial>
            <origin xyz="0.4494238793515958 0.0 0.0" rpy="0 0 0"/>
            <mass value="1" />
            <inertia ixx="100" ixy="0" ixz="0" iyy="100" iyz="0" izz="100" />
        </inertial>
        <visual>
            <origin xyz="0.4494238793515958 0.0 0.0" rpy="0 0 0"/>
            <geometry>
                <box size="0.8988477587031916 0.543225784796714 1.7711879693114405" />
            </geometry>
            <material name="Cyan">
                <color rgba="0 1.0 1.0 1.0"/>
            </material>
        </visual>
        <collision>
            <origin xyz="0.4494238793515958 0.0 0.0" rpy="0 0 0"/>
            <geometry>
                <box size="0.8988477587031916 0.543225784796714 1.7711879693114405" />
            </geometry>
        </collision>
    </link>
    <link name="2">
        <inertial>
            <origin xyz="0.0 0.43106153808475955 0.0" rpy="0 0 0"/>
            <mass value="1" />
            <inertia ixx="100" ixy="0" ixz="0" iyy="100" iyz="0" izz="100" />
        </inertial>
        <visual>
            <origin xyz="0.0 0.43106153808475955 0.0" rpy="0 0 0"/>
            <geometry>
                <box size="0.8326468940591027 0.8621230761695191 0.4766383754801621" />
            </geometry>
            <material name="Green">
                <color rgba="0 1.0 0 1.0"/>
            </material>
        </visual>
        <collision>
            <origin xyz="0.0 0.43106153808475955 0.0" rpy="0 0 0"/>
            <geometry>
                <box size="0.8326468940591027 0.8621230761695191 0.4766383754801621" />
            </geometry>
        </collision>
    </link>
    <link name="3">
        <inertial>
            <origin xyz="0.0 0.2778842035533724 0.0" rpy="0 0 0"/>
            <mass value="1" />
            <inertia ixx="100" ixy="0" ixz="0" iyy="100" iyz="0" izz="100" />
        </inertial>
        <visual>
            <origin xyz="0.0 0.2778842035533724 0.0" rpy="0 0 0"/>
            <geometry>
                <box size="1.4145253503532345 0.5557684071067448 0.3081532487596345" />
            </geometry>
            <material name="Cyan">
                <color rgba="0 1.0 1.0 1.0"/>
            </material>
        </visual>
        <collision>
            <origin xyz="0.0 0.2778842035533724 0.0" rpy="0 0 0"/>
            <geometry>
                <box size="1.4145253503532345 0.5557684071067448 0.3081532487596345" />
            </geometry>
        </collision>
    </link>
    <joint name="0_1" type="revolute">
       <parent link="0"/>
       <child  link="1"/>
       <origin rpy="0 0 0" xyz="0.7070380055376035 0.0 0.9008601726714839" />
       <axis xyz="0 1 0"/>
       <limit effort="0.0" lower="-3.14159" upper="3.14159" velocity="0.0"/>
    </joint>
    <joint name="1_2" type="revolute">
       <parent link="1"/>
       <child  link="2"/>
       <origin rpy="0 0 0" xyz="0.4494238793515958 0.271612892398357 0.0" />
       <axis xyz="1 0 0"/>
       <limit effort="0.0" lower="-3.14159" upper="3.14159" velocity="0.0"/>
    </joint>
    <joint name="0_3" type="revolute">
       <parent link="0"/>
       <child  link="3"/>
       <origin rpy="0 0 0" xyz="0.0 0.5608991887718022 0.9008601726714839" />
       <axis xyz="1 0 0"/>
       <limit effort="0.0" lower="-3.14159" upper="3.14159" velocity="0.0"/>
    </joint>
</robot>