<robot name = "robot">
    <link name="0">
        <inertial>
            <origin xyz="0 0 0.5493620504867224" rpy="0 0 0"/>
            <mass value="1" />
            <inertia ixx="100" ixy="0" ixz="0" iyy="100" iyz="0" izz="100" />
        </inertial>
        <visual>
            <origin xyz="0 0 0.5493620504867224" rpy="0 0 0"/>
            <geometry>
                <box size="1.6546147486123235 1.02093140076061 1.0967241009734447" />
            </geometry>
            <material name="Green">
                <color rgba="0 1.0 0 1.0"/>
            </material>
        </visual>
        <collision>
            <origin xyz="0 0 0.5493620504867224" rpy="0 0 0"/>
            <geometry>
                <box size="1.6546147486123235 1.02093140076061 1.0967241009734447" />
            </geometry>
        </collision>
    </link>
    <link name="1">
        <inertial>
            <origin xyz="-0.3099852412866364 0.0 0.0" rpy="0 0 0"/>
            <mass value="1" />
            <inertia ixx="100" ixy="0" ixz="0" iyy="100" iyz="0" izz="100" />
        </inertial>
        <visual>
            <origin xyz="-0.3099852412866364 0.0 0.0" rpy="0 0 0"/>
            <geometry>
                <box size="0.6199704825732728 1.2066880147582606 1.0343428150986471" />
            </geometry>
            <material name="Cyan">
                <color rgba="0 1.0 1.0 1.0"/>
            </material>
        </visual>
        <collision>
            <origin xyz="-0.3099852412866364 0.0 0.0" rpy="0 0 0"/>
            <geometry>
                <box size="0.6199704825732728 1.2066880147582606 1.0343428150986471" />
            </geometry>
        </collision>
    </link>
    <link name="2">
        <inertial>
            <origin xyz="0.0 0.9949377082648727 0.0" rpy="0 0 0"/>
            <mass value="1" />
            <inertia ixx="100" ixy="0" ixz="0" iyy="100" iyz="0" izz="100" />
        </inertial>
        <visual>
            <origin xyz="0.0 0.9949377082648727 0.0" rpy="0 0 0"/>
            <geometry>
                <box size="1.9124995148280552 1.9898754165297454 0.45782432426188124" />
            </geometry>
            <material name="Cyan">
                <color rgba="0 1.0 1.0 1.0"/>
            </material>
        </visual>
        <collision>
            <origin xyz="0.0 0.9949377082648727 0.0" rpy="0 0 0"/>
            <geometry>
                <box size="1.9124995148280552 1.9898754165297454 0.45782432426188124" />
            </geometry>
        </collision>
    </link>
    <link name="3">
        <inertial>
            <origin xyz="0.0 0.0 0.5760880533613071" rpy="0 0 0"/>
            <mass value="1" />
            <inertia ixx="100" ixy="0" ixz="0" iyy="100" iyz="0" izz="100" />
        </inertial>
        <visual>
            <origin xyz="0.0 0.0 0.5760880533613071" rpy="0 0 0"/>
            <geometry>
                <box size="0.9717619481802311 0.5753060048809789 1.1521761067226142" />
            </geometry>
            <material name="Green">
                <color rgba="0 1.0 0 1.0"/>
            </material>
        </visual>
        <collision>
            <origin xyz="0.0 0.0 0.5760880533613071" rpy="0 0 0"/>
            <geometry>
                <box size="0.9717619481802311 0.5753060048809789 1.1521761067226142" />
            </geometry>
        </collision>
    </link>
    <link name="4">
        <inertial>
            <origin xyz="-0.24338529779816565 0.0 0.0" rpy="0 0 0"/>
            <mass value="1" />
            <inertia ixx="100" ixy="0" ixz="0" iyy="100" iyz="0" izz="100" />
        </inertial>
        <visual>
            <origin xyz="-0.24338529779816565 0.0 0.0" rpy="0 0 0"/>
            <geometry>
                <box size="0.4867705955963313 0.9589221637654742 0.35098748334468194" />
            </geometry>
            <material name="Cyan">
                <color rgba="0 1.0 1.0 1.0"/>
            </material>
        </visual>
        <collision>
            <origin xyz="-0.24338529779816565 0.0 0.0" rpy="0 0 0"/>
            <geometry>
                <box size="0.4867705955963313 0.9589221637654742 0.35098748334468194" />
            </geometry>
        </collision>
    </link>
    <link name="5">
        <inertial>
            <origin xyz="0.6002295456645306 0.0 0.0" rpy="0 0 0"/>
            <mass value="1" />
            <inertia ixx="100" ixy="0" ixz="0" iyy="100" iyz="0" izz="100" />
        </inertial>
        <visual>
            <origin xyz="0.6002295456645306 0.0 0.0" rpy="0 0 0"/>
            <geometry>
                <box size="1.2004590913290611 1.3372803180314201 0.25152216123995363" />
            </geometry>
            <material name="Cyan">
                <color rgba="0 1.0 1.0 1.0"/>
            </material>
        </visual>
        <collision>
            <origin xyz="0.6002295456645306 0.0 0.0" rpy="0 0 0"/>
            <geometry>
                <box size="1.2004590913290611 1.3372803180314201 0.25152216123995363" />
            </geometry>
        </collision>
    </link>
    <joint name="0_1" type="revolute">
       <parent link="0"/>
       <child  link="1"/>
       <origin rpy="0 0 0" xyz="-0.8273073743061617 0.0 0.5493620504867224" />
       <axis xyz="0 0 1"/>
       <limit effort="0.0" lower="-3.14159" upper="3.14159" velocity="0.0"/>
    </joint>
    <joint name="1_2" type="revolute">
       <parent link="1"/>
       <child  link="2"/>
       <origin rpy="0 0 0" xyz="-0.3099852412866364 0.6033440073791303 0.0" />
       <axis xyz="1 0 0"/>
       <limit effort="0.0" lower="-3.14159" upper="3.14159" velocity="0.0"/>
    </joint>
    <joint name="2_3" type="revolute">
       <parent link="2"/>
       <child  link="3"/>
       <origin rpy="0 0 0" xyz="0.0 0.9949377082648727 0.22891216213094062" />
       <axis xyz="1 0 0"/>
       <limit effort="0.0" lower="-3.14159" upper="3.14159" velocity="0.0"/>
    </joint>
    <joint name="1_4" type="revolute">
       <parent link="1"/>
       <child  link="4"/>
       <origin rpy="0 0 0" xyz="-0.6199704825732728 0.0 0.0" />
       <axis xyz="0 1 0"/>
       <limit effort="0.0" lower="-3.14159" upper="3.14159" velocity="0.0"/>
    </joint>
    <joint name="3_5" type="revolute">
       <parent link="3"/>
       <child  link="5"/>
       <origin rpy="0 0 0" xyz="0.48588097409011555 0.0 0.5760880533613071" />
       <axis xyz="0 0 1"/>
       <limit effort="0.0" lower="-3.14159" upper="3.14159" velocity="0.0"/>
    </joint>
</robot>