<robot name = "robot">
    <link name="0">
        <inertial>
            <origin xyz="0 0 0.17165947105486212" rpy="0 0 0"/>
            <mass value="1" />
            <inertia ixx="100" ixy="0" ixz="0" iyy="100" iyz="0" izz="100" />
        </inertial>
        <visual>
            <origin xyz="0 0 0.17165947105486212" rpy="0 0 0"/>
            <geometry>
                <box size="1.443967358074493 0.2839814412919398 0.34131894210972424" />
            </geometry>
            <material name="Green">
                <color rgba="0 1.0 0 1.0"/>
            </material>
        </visual>
        <collision>
            <origin xyz="0 0 0.17165947105486212" rpy="0 0 0"/>
            <geometry>
                <box size="1.443967358074493 0.2839814412919398 0.34131894210972424" />
            </geometry>
        </collision>
    </link>
    <link name="1">
        <inertial>
            <origin xyz="0.0 0.0 0.5474159672104237" rpy="0 0 0"/>
            <mass value="1" />
            <inertia ixx="100" ixy="0" ixz="0" iyy="100" iyz="0" izz="100" />
        </inertial>
        <visual>
            <origin xyz="0.0 0.0 0.5474159672104237" rpy="0 0 0"/>
            <geometry>
                <box size="1.4092410161866442 1.9345776349562458 1.0948319344208475" />
            </geometry>
            <material name="Cyan">
                <color rgba="0 1.0 1.0 1.0"/>
            </material>
        </visual>
        <collision>
            <origin xyz="0.0 0.0 0.5474159672104237" rpy="0 0 0"/>
            <geometry>
                <box size="1.4092410161866442 1.9345776349562458 1.0948319344208475" />
            </geometry>
        </collision>
    </link>
    <joint name="0_1" type="revolute">
       <parent link="0"/>
       <child  link="1"/>
       <origin rpy="0 0 0" xyz="0.0 0.0 0.34231894210972424" />
       <axis xyz="1 0 0"/>
       <limit effort="0.0" lower="-3.14159" upper="3.14159" velocity="0.0"/>
    </joint>
</robot>