<robot name = "robot">
    <link name="0">
        <inertial>
            <origin xyz="0 0 0.8236812868065558" rpy="0 0 0"/>
            <mass value="1" />
            <inertia ixx="100" ixy="0" ixz="0" iyy="100" iyz="0" izz="100" />
        </inertial>
        <visual>
            <origin xyz="0 0 0.8236812868065558" rpy="0 0 0"/>
            <geometry>
                <box size="0.8812404873287742 0.5818758936174315 1.6453625736131117" />
            </geometry>
            <material name="Green">
                <color rgba="0 1.0 0 1.0"/>
            </material>
        </visual>
        <collision>
            <origin xyz="0 0 0.8236812868065558" rpy="0 0 0"/>
            <geometry>
                <box size="0.8812404873287742 0.5818758936174315 1.6453625736131117" />
            </geometry>
        </collision>
    </link>
    <link name="1">
        <inertial>
            <origin xyz="0.0 0.0 0.2642024683633726" rpy="0 0 0"/>
            <mass value="1" />
            <inertia ixx="100" ixy="0" ixz="0" iyy="100" iyz="0" izz="100" />
        </inertial>
        <visual>
            <origin xyz="0.0 0.0 0.2642024683633726" rpy="0 0 0"/>
            <geometry>
                <box size="1.1180146624451246 0.32024172234074344 0.5284049367267452" />
            </geometry>
            <material name="Cyan">
                <color rgba="0 1.0 1.0 1.0"/>
            </material>
        </visual>
        <collision>
            <origin xyz="0.0 0.0 0.2642024683633726" rpy="0 0 0"/>
            <geometry>
                <box size="1.1180146624451246 0.32024172234074344 0.5284049367267452" />
            </geometry>
        </collision>
    </link>
    <link name="2">
        <inertial>
            <origin xyz="0.0 0.9529593980791774 0.0" rpy="0 0 0"/>
            <mass value="1" />
            <inertia ixx="100" ixy="0" ixz="0" iyy="100" iyz="0" izz="100" />
        </inertial>
        <visual>
            <origin xyz="0.0 0.9529593980791774 0.0" rpy="0 0 0"/>
            <geometry>
                <box size="1.8415305723270765 1.9059187961583548 0.6125575226829082" />
            </geometry>
            <material name="Green">
                <color rgba="0 1.0 0 1.0"/>
            </material>
        </visual>
        <collision>
            <origin xyz="0.0 0.9529593980791774 0.0" rpy="0 0 0"/>
            <geometry>
                <box size="1.8415305723270765 1.9059187961583548 0.6125575226829082" />
            </geometry>
        </collision>
    </link>
    <link name="3">
        <inertial>
            <origin xyz="0.0 -0.3263072406455614 0.0" rpy="0 0 0"/>
            <mass value="1" />
            <inertia ixx="100" ixy="0" ixz="0" iyy="100" iyz="0" izz="100" />
        </inertial>
        <visual>
            <origin xyz="0.0 -0.3263072406455614 0.0" rpy="0 0 0"/>
            <geometry>
                <box size="0.8909593570382381 0.6526144812911228 0.9194832464245571" />
            </geometry>
            <material name="Cyan">
                <color rgba="0 1.0 1.0 1.0"/>
            </material>
        </visual>
        <collision>
            <origin xyz="0.0 -0.3263072406455614 0.0" rpy="0 0 0"/>
            <geometry>
                <box size="0.8909593570382381 0.6526144812911228 0.9194832464245571" />
            </geometry>
        </collision>
    </link>
    <link name="4">
        <inertial>
            <origin xyz="-0.9652008226074801 0.0 0.0" rpy="0 0 0"/>
            <mass value="1" />
            <inertia ixx="100" ixy="0" ixz="0" iyy="100" iyz="0" izz="100" />
        </inertial>
        <visual>
            <origin xyz="-0.9652008226074801 0.0 0.0" rpy="0 0 0"/>
            <geometry>
                <box size="1.9304016452149602 0.5531943972705731 1.3417707880062353" />
            </geometry>
            <material name="Green">
                <color rgba="0 1.0 0 1.0"/>
            </material>
        </visual>
        <collision>
            <origin xyz="-0.9652008226074801 0.0 0.0" rpy="0 0 0"/>
            <geometry>
                <box size="1.9304016452149602 0.5531943972705731 1.3417707880062353" />
            </geometry>
        </collision>
    </link>
    <link name="5">
        <inertial>
            <origin xyz="0.7930572602226937 0.0 0.0" rpy="0 0 0"/>
            <mass value="1" />
            <inertia ixx="100" ixy="0" ixz="0" iyy="100" iyz="0" izz="100" />
        </inertial>
        <visual>
            <origin xyz="0.7930572602226937 0.0 0.0" rpy="0 0 0"/>
            <geometry>
                <box size="1.5861145204453875 1.3160175171916932 1.3742130414878233" />
            </geometry>
            <material name="Green">
                <color rgba="0 1.0 0 1.0"/>
            </material>
        </visual>
        <collision>
            <origin xyz="0.7930572602226937 0.0 0.0" rpy="0 0 0"/>
            <geometry>
                <box size="1.5861145204453875 1.3160175171916932 1.3742130414878233" />
            </geometry>
        </collision>
    </link>
    <joint name="0_1" type="revolute">
       <parent link="0"/>
       <child  link="1"/>
       <origin rpy="0 0 0" xyz="0.0 0.0 1.6463625736131116" />
       <axis xyz="0 1 0"/>
       <limit effort="0.0" lower="-3.14159" upper="3.14159" velocity="0.0"/>
    </joint>
    <joint name="1_2" type="revolute">
       <parent link="1"/>
       <child  link="2"/>
       <origin rpy="0 0 0" xyz="0.0 0.16012086117037172 0.2642024683633726" />
       <axis xyz="1 0 0"/>
       <limit effort="0.0" lower="-3.14159" upper="3.14159" velocity="0.0"/>
    </joint>
    <joint name="0_3" type="revolute">
       <parent link="0"/>
       <child  link="3"/>
       <origin rpy="0 0 0" xyz="0.0 -0.29093794680871576 0.8236812868065558" />
       <axis xyz="1 0 0"/>
       <limit effort="0.0" lower="-3.14159" upper="3.14159" velocity="0.0"/>
    </joint>
    <joint name="3_4" type="revolute">
       <parent link="3"/>
       <child  link="4"/>
       <origin rpy="0 0 0" xyz="-0.44547967851911907 -0.3263072406455614 0.0" />
       <axis xyz="0 0 1"/>
       <limit effort="0.0" lower="-3.14159" upper="3.14159" velocity="0.0"/>
    </joint>
    <joint name="3_5" type="revolute">
       <parent link="3"/>
       <child  link="5"/>
       <origin rpy="0 0 0" xyz="0.44547967851911907 -0.3263072406455614 0.0" />
       <axis xyz="0 0 1"/>
       <limit effort="0.0" lower="-3.14159" upper="3.14159" velocity="0.0"/>
    </joint>
</robot>