<robot name = "robot">
    <link name="0">
        <inertial>
            <origin xyz="0 0 0.5585735798039498" rpy="0 0 0"/>
            <mass value="1" />
            <inertia ixx="100" ixy="0" ixz="0" iyy="100" iyz="0" izz="100" />
        </inertial>
        <visual>
            <origin xyz="0 0 0.5585735798039498" rpy="0 0 0"/>
            <geometry>
                <box size="0.839146276895934 0.41145033641737205 1.1151471596078997" />
            </geometry>
            <material name="Green">
                <color rgba="0 1.0 0 1.0"/>
            </material>
        </visual>
        <collision>
            <origin xyz="0 0 0.5585735798039498" rpy="0 0 0"/>
            <geometry>
                <box size="0.839146276895934 0.41145033641737205 1.1151471596078997" />
            </geometry>
        </collision>
    </link>
    <link name="1">
        <inertial>
            <origin xyz="-0.6648766780183126 0.0 0.0" rpy="0 0 0"/>
            <mass value="1" />
            <inertia ixx="100" ixy="0" ixz="0" iyy="100" iyz="0" izz="100" />
        </inertial>
        <visual>
            <origin xyz="-0.6648766780183126 0.0 0.0" rpy="0 0 0"/>
            <geometry>
                <box size="1.3297533560366253 0.6844004735720073 0.7184922753506449" />
            </geometry>
            <material name="Cyan">
                <color rgba="0 1.0 1.0 1.0"/>
            </material>
        </visual>
        <collision>
            <origin xyz="-0.6648766780183126 0.0 0.0" rpy="0 0 0"/>
            <geometry>
                <box size="1.3297533560366253 0.6844004735720073 0.7184922753506449" />
            </geometry>
        </collision>
    </link>
    <link name="2">
        <inertial>
            <origin xyz="0.0 0.0 0.44339521799894865" rpy="0 0 0"/>
            <mass value="1" />
            <inertia ixx="100" ixy="0" ixz="0" iyy="100" iyz="0" izz="100" />
        </inertial>
        <visual>
            <origin xyz="0.0 0.0 0.44339521799894865" rpy="0 0 0"/>
            <geometry>
                <box size="1.0072794899036048 0.6093869853477389 0.8867904359978973" />
            </geometry>
            <material name="Cyan">
                <color rgba="0 1.0 1.0 1.0"/>
            </material>
        </visual>
        <collision>
            <origin xyz="0.0 0.0 0.44339521799894865" rpy="0 0 0"/>
            <geometry>
                <box size="1.0072794899036048 0.6093869853477389 0.8867904359978973" />
            </geometry>
        </collision>
    </link>
    <link name="3">
        <inertial>
            <origin xyz="0.7640595997981302 0.0 0.0" rpy="0 0 0"/>
            <mass value="1" />
            <inertia ixx="100" ixy="0" ixz="0" iyy="100" iyz="0" izz="100" />
        </inertial>
        <visual>
            <origin xyz="0.7640595997981302 0.0 0.0" rpy="0 0 0"/>
            <geometry>
                <box size="1.5281191995962604 0.861897537893317 1.5891190763966787" />
            </geometry>
            <material name="Cyan">
                <color rgba="0 1.0 1.0 1.0"/>
            </material>
        </visual>
        <collision>
            <origin xyz="0.7640595997981302 0.0 0.0" rpy="0 0 0"/>
            <geometry>
                <box size="1.5281191995962604 0.861897537893317 1.5891190763966787" />
            </geometry>
        </collision>
    </link>
    <joint name="0_1" type="revolute">
       <parent link="0"/>
       <child  link="1"/>
       <origin rpy="0 0 0" xyz="-0.419573138447967 0.0 0.5585735798039498" />
       <axis xyz="0 0 1"/>
       <limit effort="0.0" lower="-3.14159" upper="3.14159" velocity="0.0"/>
    </joint>
    <joint name="0_2" type="revolute">
       <parent link="0"/>
       <child  link="2"/>
       <origin rpy="0 0 0" xyz="0.0 0.0 1.1161471596078996" />
       <axis xyz="0 1 0"/>
       <limit effort="0.0" lower="-3.14159" upper="3.14159" velocity="0.0"/>
    </joint>
    <joint name="2_3" type="revolute">
       <parent link="2"/>
       <child  link="3"/>
       <origin rpy="0 0 0" xyz="0.5036397449518024 0.0 0.44339521799894865" />
       <axis xyz="0 1 0"/>
       <limit effort="0.0" lower="-3.14159" upper="3.14159" velocity="0.0"/>
    </joint>
</robot>