<robot name = "robot">
    <link name="0">
        <inertial>
            <origin xyz="0 0 0.23545453325067608" rpy="0 0 0"/>
            <mass value="1" />
            <inertia ixx="100" ixy="0" ixz="0" iyy="100" iyz="0" izz="100" />
        </inertial>
        <visual>
            <origin xyz="0 0 0.23545453325067608" rpy="0 0 0"/>
            <geometry>
                <box size="1.6088102430073858 1.0713522367863126 0.46890906650135217" />
            </geometry>
            <material name="Green">
                <color rgba="0 1.0 0 1.0"/>
            </material>
        </visual>
        <collision>
            <origin xyz="0 0 0.23545453325067608" rpy="0 0 0"/>
            <geometry>
                <box size="1.6088102430073858 1.0713522367863126 0.46890906650135217" />
            </geometry>
        </collision>
    </link>
    <link name="1">
        <inertial>
            <origin xyz="0.0 0.0 0.9788570608153004" rpy="0 0 0"/>
            <mass value="1" />
            <inertia ixx="100" ixy="0" ixz="0" iyy="100" iyz="0" izz="100" />
        </inertial>
        <visual>
            <origin xyz="0.0 0.0 0.9788570608153004" rpy="0 0 0"/>
            <geometry>
                <box size="0.37935069338660216 0.6363363681409235 1.9577141216306009" />
            </geometry>
            <material name="Green">
                <color rgba="0 1.0 0 1.0"/>
            </material>
        </visual>
        <collision>
            <origin xyz="0.0 0.0 0.9788570608153004" rpy="0 0 0"/>
            <geometry>
                <box size="0.37935069338660216 0.6363363681409235 1.9577141216306009" />
            </geometry>
        </collision>
    </link>
    <link name="2">
        <inertial>
            <origin xyz="0.0 0.7108362930407122 0.0" rpy="0 0 0"/>
            <mass value="1" />
            <inertia ixx="100" ixy="0" ixz="0" iyy="100" iyz="0" izz="100" />
        </inertial>
        <visual>
            <origin xyz="0.0 0.7108362930407122 0.0" rpy="0 0 0"/>
            <geometry>
                <box size="0.6999989505112126 1.4216725860814243 1.8000911375010002" />
            </geometry>
            <material name="Cyan">
                <color rgba="0 1.0 1.0 1.0"/>
            </material>
        </visual>
        <collision>
            <origin xyz="0.0 0.7108362930407122 0.0" rpy="0 0 0"/>
            <geometry>
                <box size="0.6999989505112126 1.4216725860814243 1.8000911375010002" />
            </geometry>
        </collision>
    </link>
    <joint name="0_1" type="revolute">
       <parent link="0"/>
       <child  link="1"/>
       <origin rpy="0 0 0" xyz="0.0 0.0 0.46990906650135217" />
       <axis xyz="1 0 0"/>
       <limit effort="0.0" lower="-3.14159" upper="3.14159" velocity="0.0"/>
    </joint>
    <joint name="1_2" type="revolute">
       <parent link="1"/>
       <child  link="2"/>
       <origin rpy="0 0 0" xyz="0.0 0.31816818407046177 0.9788570608153004" />
       <axis xyz="1 0 0"/>
       <limit effort="0.0" lower="-3.14159" upper="3.14159" velocity="0.0"/>
    </joint>
</robot>