<robot name = "robot">
    <link name="0">
        <inertial>
            <origin xyz="0 0 0.1335025151112683" rpy="0 0 0"/>
            <mass value="1" />
            <inertia ixx="100" ixy="0" ixz="0" iyy="100" iyz="0" izz="100" />
        </inertial>
        <visual>
            <origin xyz="0 0 0.1335025151112683" rpy="0 0 0"/>
            <geometry>
                <box size="1.8825507073897763 0.4507335886444287 0.2650050302225366" />
            </geometry>
            <material name="Green">
                <color rgba="0 1.0 0 1.0"/>
            </material>
        </visual>
        <collision>
            <origin xyz="0 0 0.1335025151112683" rpy="0 0 0"/>
            <geometry>
                <box size="1.8825507073897763 0.4507335886444287 0.2650050302225366" />
            </geometry>
        </collision>
    </link>
    <link name="1">
        <inertial>
            <origin xyz="0.0 0.0 0.42359432594239915" rpy="0 0 0"/>
            <mass value="1" />
            <inertia ixx="100" ixy="0" ixz="0" iyy="100" iyz="0" izz="100" />
        </inertial>
        <visual>
            <origin xyz="0.0 0.0 0.42359432594239915" rpy="0 0 0"/>
            <geometry>
                <box size="1.513732716390617 0.7235859496020003 0.8471886518847983" />
            </geometry>
            <material name="Cyan">
                <color rgba="0 1.0 1.0 1.0"/>
            </material>
        </visual>
        <collision>
            <origin xyz="0.0 0.0 0.42359432594239915" rpy="0 0 0"/>
            <geometry>
                <box size="1.513732716390617 0.7235859496020003 0.8471886518847983" />
            </geometry>
        </collision>
    </link>
    <link name="2">
        <inertial>
            <origin xyz="0.0 0.0 0.7253283086593318" rpy="0 0 0"/>
            <mass value="1" />
            <inertia ixx="100" ixy="0" ixz="0" iyy="100" iyz="0" izz="100" />
        </inertial>
        <visual>
            <origin xyz="0.0 0.0 0.7253283086593318" rpy="0 0 0"/>
            <geometry>
                <box size="1.9017323871968503 1.8231468672761109 1.4506566173186637" />
            </geometry>
            <material name="Cyan">
                <color rgba="0 1.0 1.0 1.0"/>
            </material>
        </visual>
        <collision>
            <origin xyz="0.0 0.0 0.7253283086593318" rpy="0 0 0"/>
            <geometry>
                <box size="1.9017323871968503 1.8231468672761109 1.4506566173186637" />
            </geometry>
        </collision>
    </link>
    <joint name="0_1" type="revolute">
       <parent link="0"/>
       <child  link="1"/>
       <origin rpy="0 0 0" xyz="0.0 0.0 0.2660050302225366" />
       <axis xyz="1 0 0"/>
       <limit effort="0.0" lower="-3.14159" upper="3.14159" velocity="0.0"/>
    </joint>
    <joint name="1_2" type="revolute">
       <parent link="1"/>
       <child  link="2"/>
       <origin rpy="0 0 0" xyz="0.0 0.0 0.8471886518847983" />
       <axis xyz="1 0 0"/>
       <limit effort="0.0" lower="-3.14159" upper="3.14159" velocity="0.0"/>
    </joint>
</robot>