<robot name = "robot">
    <link name="0">
        <inertial>
            <origin xyz="0 0 0.46511495189386604" rpy="0 0 0"/>
            <mass value="1" />
            <inertia ixx="100" ixy="0" ixz="0" iyy="100" iyz="0" izz="100" />
        </inertial>
        <visual>
            <origin xyz="0 0 0.46511495189386604" rpy="0 0 0"/>
            <geometry>
                <box size="0.37875509485779335 0.9489985980550619 0.9302299037877321" />
            </geometry>
            <material name="Cyan">
                <color rgba="0 1.0 1.0 1.0"/>
            </material>
        </visual>
        <collision>
            <origin xyz="0 0 0.46511495189386604" rpy="0 0 0"/>
            <geometry>
                <box size="0.37875509485779335 0.9489985980550619 0.9302299037877321" />
            </geometry>
        </collision>
    </link>
    <joint name="0_1" type="revolute">
       <parent link="0"/>
       <child  link="1"/>
       <origin rpy="0 0 0" xyz="0 0.47449929902753096 0.46511495189386604" />
       <axis xyz="1 0 0"/>
       <limit effort="0.0" lower="-3.14159" upper="3.14159" velocity="0.0"/>
    </joint>
    <link name="1">
        <inertial>
            <origin xyz="0 0.25775375906846215 0" rpy="0 0 0"/>
            <mass value="1" />
            <inertia ixx="100" ixy="0" ixz="0" iyy="100" iyz="0" izz="100" />
        </inertial>
        <visual>
            <origin xyz="0 0.25775375906846215 0" rpy="0 0 0"/>
            <geometry>
                <box size="0.9662135757278909 0.5155075181369243 0.8494884425277307" />
            </geometry>
            <material name="Cyan">
                <color rgba="0 1.0 1.0 1.0"/>
            </material>
        </visual>
        <collision>
            <origin xyz="0 0.25775375906846215 0" rpy="0 0 0"/>
            <geometry>
                <box size="0.9662135757278909 0.5155075181369243 0.8494884425277307" />
            </geometry>
        </collision>
    </link>
    <joint name="1_2" type="revolute">
       <parent link="1"/>
       <child  link="2"/>
       <origin rpy="0 0 0" xyz="0 0.5155075181369243 0" />
       <axis xyz="1 0 0"/>
       <limit effort="0.0" lower="-3.14159" upper="3.14159" velocity="0.0"/>
    </joint>
    <link name="2">
        <inertial>
            <origin xyz="0 0.9565918394436762 0" rpy="0 0 0"/>
            <mass value="1" />
            <inertia ixx="100" ixy="0" ixz="0" iyy="100" iyz="0" izz="100" />
        </inertial>
        <visual>
            <origin xyz="0 0.9565918394436762 0" rpy="0 0 0"/>
            <geometry>
                <box size="1.8896917668849558 1.9131836788873524 0.6470619979557618" />
            </geometry>
            <material name="Green">
                <color rgba="0 1.0 0 1.0"/>
            </material>
        </visual>
        <collision>
            <origin xyz="0 0.9565918394436762 0" rpy="0 0 0"/>
            <geometry>
                <box size="1.8896917668849558 1.9131836788873524 0.6470619979557618" />
            </geometry>
        </collision>
    </link>
</robot>