<robot name = "robot">
    <link name="0">
        <inertial>
            <origin xyz="0 0 0.8630731716523888" rpy="0 0 0"/>
            <mass value="1" />
            <inertia ixx="100" ixy="0" ixz="0" iyy="100" iyz="0" izz="100" />
        </inertial>
        <visual>
            <origin xyz="0 0 0.8630731716523888" rpy="0 0 0"/>
            <geometry>
                <box size="0.3384370963625959 0.4041539747163599 1.6331402187251536" />
            </geometry>
            <material name="Cyan">
                <color rgba="0 1.0 1.0 1.0"/>
            </material>
        </visual>
        <collision>
            <origin xyz="0 0 0.8630731716523888" rpy="0 0 0"/>
            <geometry>
                <box size="0.3384370963625959 0.4041539747163599 1.6331402187251536" />
            </geometry>
        </collision>
    </link>
    <joint name="0_1" type="revolute">
       <parent link="0"/>
       <child  link="1"/>
       <origin rpy="0 0 0" xyz="0 0.20207698735817994 0.8630731716523888" />
       <axis xyz="1 0 0"/>
       <limit effort="0.0" lower="-3.14159" upper="3.14159" velocity="0.0"/>
    </joint>
    <link name="1">
        <inertial>
            <origin xyz="0 0.835978610804579 0" rpy="0 0 0"/>
            <mass value="1" />
            <inertia ixx="100" ixy="0" ixz="0" iyy="100" iyz="0" izz="100" />
        </inertial>
        <visual>
            <origin xyz="0 0.835978610804579 0" rpy="0 0 0"/>
            <geometry>
                <box size="1.1639650783851716 1.671957221609158 1.6976180488184895" />
            </geometry>
            <material name="Cyan">
                <color rgba="0 1.0 1.0 1.0"/>
            </material>
        </visual>
        <collision>
            <origin xyz="0 0.835978610804579 0" rpy="0 0 0"/>
            <geometry>
                <box size="1.1639650783851716 1.671957221609158 1.6976180488184895" />
            </geometry>
        </collision>
    </link>
    <joint name="1_2" type="revolute">
       <parent link="1"/>
       <child  link="2"/>
       <origin rpy="0 0 0" xyz="0 0.835978610804579 0" />
       <axis xyz="1 0 0"/>
       <limit effort="0.0" lower="-3.14159" upper="3.14159" velocity="0.0"/>
    </joint>
    <link name="2">
        <inertial>
            <origin xyz="0 0.15009856679873765 0" rpy="0 0 0"/>
            <mass value="1" />
            <inertia ixx="100" ixy="0" ixz="0" iyy="100" iyz="0" izz="100" />
        </inertial>
        <visual>
            <origin xyz="0 0.15009856679873765 0" rpy="0 0 0"/>
            <geometry>
                <box size="0.43769033884155767 0.3001971335974753 0.4760383940919556" />
            </geometry>
            <material name="Cyan">
                <color rgba="0 1.0 1.0 1.0"/>
            </material>
        </visual>
        <collision>
            <origin xyz="0 0.15009856679873765 0" rpy="0 0 0"/>
            <geometry>
                <box size="0.43769033884155767 0.3001971335974753 0.4760383940919556" />
            </geometry>
        </collision>
    </link>
    <joint name="2_3" type="revolute">
       <parent link="2"/>
       <child  link="3"/>
       <origin rpy="0 0 0" xyz="0 0.15009856679873765 0" />
       <axis xyz="1 0 0"/>
       <limit effort="0.0" lower="-3.14159" upper="3.14159" velocity="0.0"/>
    </joint>
    <link name="3">
        <inertial>
            <origin xyz="0 0.8028910965941342 0" rpy="0 0 0"/>
            <mass value="1" />
            <inertia ixx="100" ixy="0" ixz="0" iyy="100" iyz="0" izz="100" />
        </inertial>
        <visual>
            <origin xyz="0 0.8028910965941342 0" rpy="0 0 0"/>
            <geometry>
                <box size="1.3355461546378355 1.6057821931882683 0.6822955106739677" />
            </geometry>
            <material name="Cyan">
                <color rgba="0 1.0 1.0 1.0"/>
            </material>
        </visual>
        <collision>
            <origin xyz="0 0.8028910965941342 0" rpy="0 0 0"/>
            <geometry>
                <box size="1.3355461546378355 1.6057821931882683 0.6822955106739677" />
            </geometry>
        </collision>
    </link>
    <joint name="3_4" type="revolute">
       <parent link="3"/>
       <child  link="4"/>
       <origin rpy="0 0 0" xyz="0 0.8028910965941342 0" />
       <axis xyz="1 0 0"/>
       <limit effort="0.0" lower="-3.14159" upper="3.14159" velocity="0.0"/>
    </joint>
    <link name="4">
        <inertial>
            <origin xyz="0 0.7730466794593861 0" rpy="0 0 0"/>
            <mass value="1" />
            <inertia ixx="100" ixy="0" ixz="0" iyy="100" iyz="0" izz="100" />
        </inertial>
        <visual>
            <origin xyz="0 0.7730466794593861 0" rpy="0 0 0"/>
            <geometry>
                <box size="1.6346836953702488 1.5460933589187722 0.8949005886451457" />
            </geometry>
            <material name="Cyan">
                <color rgba="0 1.0 1.0 1.0"/>
            </material>
        </visual>
        <collision>
            <origin xyz="0 0.7730466794593861 0" rpy="0 0 0"/>
            <geometry>
                <box size="1.6346836953702488 1.5460933589187722 0.8949005886451457" />
            </geometry>
        </collision>
    </link>
    <joint name="4_5" type="revolute">
       <parent link="4"/>
       <child  link="5"/>
       <origin rpy="0 0 0" xyz="0 0.7730466794593861 0" />
       <axis xyz="1 0 0"/>
       <limit effort="0.0" lower="-3.14159" upper="3.14159" velocity="0.0"/>
    </joint>
    <link name="5">
        <inertial>
            <origin xyz="0 0.25813679494231434 0" rpy="0 0 0"/>
            <mass value="1" />
            <inertia ixx="100" ixy="0" ixz="0" iyy="100" iyz="0" izz="100" />
        </inertial>
        <visual>
            <origin xyz="0 0.25813679494231434 0" rpy="0 0 0"/>
            <geometry>
                <box size="0.9251129346317055 0.5162735898846287 1.7261463433047777" />
            </geometry>
            <material name="Cyan">
                <color rgba="0 1.0 1.0 1.0"/>
            </material>
        </visual>
        <collision>
            <origin xyz="0 0.25813679494231434 0" rpy="0 0 0"/>
            <geometry>
                <box size="0.9251129346317055 0.5162735898846287 1.7261463433047777" />
            </geometry>
        </collision>
    </link>
</robot>