<robot name = "robot">
    <link name="0">
        <inertial>
            <origin xyz="0 0 0.8939873978337342" rpy="0 0 0"/>
            <mass value="1" />
            <inertia ixx="100" ixy="0" ixz="0" iyy="100" iyz="0" izz="100" />
        </inertial>
        <visual>
            <origin xyz="0 0 0.8939873978337342" rpy="0 0 0"/>
            <geometry>
                <box size="0.7234427483387669 1.5134160299757053 1.615233815397521" />
            </geometry>
            <material name="Cyan">
                <color rgba="0 1.0 1.0 1.0"/>
            </material>
        </visual>
        <collision>
            <origin xyz="0 0 0.8939873978337342" rpy="0 0 0"/>
            <geometry>
                <box size="0.7234427483387669 1.5134160299757053 1.615233815397521" />
            </geometry>
        </collision>
    </link>
    <joint name="0_1" type="revolute">
       <parent link="0"/>
       <child  link="1"/>
       <origin rpy="0 0 0" xyz="0 0.7567080149878527 0.8939873978337342" />
       <axis xyz="1 0 0"/>
       <limit effort="0.0" lower="-3.14159" upper="3.14159" velocity="0.0"/>
    </joint>
    <link name="1">
        <inertial>
            <origin xyz="0 0.1451438915057343 0" rpy="0 0 0"/>
            <mass value="1" />
            <inertia ixx="100" ixy="0" ixz="0" iyy="100" iyz="0" izz="100" />
        </inertial>
        <visual>
            <origin xyz="0 0.1451438915057343 0" rpy="0 0 0"/>
            <geometry>
                <box size="1.176484313375401 0.2902877830114686 1.3025215708002236" />
            </geometry>
            <material name="Cyan">
                <color rgba="0 1.0 1.0 1.0"/>
            </material>
        </visual>
        <collision>
            <origin xyz="0 0.1451438915057343 0" rpy="0 0 0"/>
            <geometry>
                <box size="1.176484313375401 0.2902877830114686 1.3025215708002236" />
            </geometry>
        </collision>
    </link>
    <joint name="1_2" type="revolute">
       <parent link="1"/>
       <child  link="2"/>
       <origin rpy="0 0 0" xyz="0 0.1451438915057343 0" />
       <axis xyz="1 0 0"/>
       <limit effort="0.0" lower="-3.14159" upper="3.14159" velocity="0.0"/>
    </joint>
    <link name="2">
        <inertial>
            <origin xyz="0 0.5134859810662822 0" rpy="0 0 0"/>
            <mass value="1" />
            <inertia ixx="100" ixy="0" ixz="0" iyy="100" iyz="0" izz="100" />
        </inertial>
        <visual>
            <origin xyz="0 0.5134859810662822 0" rpy="0 0 0"/>
            <geometry>
                <box size="1.3883016244495174 1.0269719621325644 0.5139421297434353" />
            </geometry>
            <material name="Cyan">
                <color rgba="0 1.0 1.0 1.0"/>
            </material>
        </visual>
        <collision>
            <origin xyz="0 0.5134859810662822 0" rpy="0 0 0"/>
            <geometry>
                <box size="1.3883016244495174 1.0269719621325644 0.5139421297434353" />
            </geometry>
        </collision>
    </link>
    <joint name="2_3" type="revolute">
       <parent link="2"/>
       <child  link="3"/>
       <origin rpy="0 0 0" xyz="0 0.5134859810662822 0" />
       <axis xyz="1 0 0"/>
       <limit effort="0.0" lower="-3.14159" upper="3.14159" velocity="0.0"/>
    </joint>
    <link name="3">
        <inertial>
            <origin xyz="0 0.7218811416284325 0" rpy="0 0 0"/>
            <mass value="1" />
            <inertia ixx="100" ixy="0" ixz="0" iyy="100" iyz="0" izz="100" />
        </inertial>
        <visual>
            <origin xyz="0 0.7218811416284325 0" rpy="0 0 0"/>
            <geometry>
                <box size="1.7093377707340371 1.443762283256865 1.2953982034050262" />
            </geometry>
            <material name="Cyan">
                <color rgba="0 1.0 1.0 1.0"/>
            </material>
        </visual>
        <collision>
            <origin xyz="0 0.7218811416284325 0" rpy="0 0 0"/>
            <geometry>
                <box size="1.7093377707340371 1.443762283256865 1.2953982034050262" />
            </geometry>
        </collision>
    </link>
    <joint name="3_4" type="revolute">
       <parent link="3"/>
       <child  link="4"/>
       <origin rpy="0 0 0" xyz="0 0.7218811416284325 0" />
       <axis xyz="1 0 0"/>
       <limit effort="0.0" lower="-3.14159" upper="3.14159" velocity="0.0"/>
    </joint>
    <link name="4">
        <inertial>
            <origin xyz="0 0.5090662176627705 0" rpy="0 0 0"/>
            <mass value="1" />
            <inertia ixx="100" ixy="0" ixz="0" iyy="100" iyz="0" izz="100" />
        </inertial>
        <visual>
            <origin xyz="0 0.5090662176627705 0" rpy="0 0 0"/>
            <geometry>
                <box size="1.449295725742621 1.018132435325541 1.7879747956674683" />
            </geometry>
            <material name="Cyan">
                <color rgba="0 1.0 1.0 1.0"/>
            </material>
        </visual>
        <collision>
            <origin xyz="0 0.5090662176627705 0" rpy="0 0 0"/>
            <geometry>
                <box size="1.449295725742621 1.018132435325541 1.7879747956674683" />
            </geometry>
        </collision>
    </link>
</robot>